{
 "cells": [
  {
   "cell_type": "code",
   "execution_count": null,
   "metadata": {},
   "outputs": [
    {
     "name": "stderr",
     "output_type": "stream",
     "text": [
      "ERROR:root:Internal Python error in the inspect module.\n",
      "Below is the traceback from this internal error.\n",
      "\n",
      "ERROR:root:Internal Python error in the inspect module.\n",
      "Below is the traceback from this internal error.\n",
      "\n",
      "ERROR:root:Internal Python error in the inspect module.\n",
      "Below is the traceback from this internal error.\n",
      "\n"
     ]
    },
    {
     "name": "stdout",
     "output_type": "stream",
     "text": [
      "Traceback (most recent call last):\n",
      "  File \"C:\\Users\\Hameez\\.conda\\envs\\gpu_tf\\lib\\site-packages\\IPython\\core\\interactiveshell.py\", line 3418, in run_code\n",
      "    exec(code_obj, self.user_global_ns, self.user_ns)\n",
      "  File \"<ipython-input-1-e3e6886b4170>\", line 5, in <module>\n",
      "    from tensorflow.keras.applications.MobileNet import preprocess_input, decode_predictions\n",
      "ModuleNotFoundError: No module named 'tensorflow.keras.applications.MobileNet'\n",
      "\n",
      "During handling of the above exception, another exception occurred:\n",
      "\n",
      "Traceback (most recent call last):\n",
      "  File \"C:\\Users\\Hameez\\.conda\\envs\\gpu_tf\\lib\\site-packages\\IPython\\core\\interactiveshell.py\", line 2045, in showtraceback\n",
      "    stb = value._render_traceback_()\n",
      "AttributeError: 'ModuleNotFoundError' object has no attribute '_render_traceback_'\n",
      "\n",
      "During handling of the above exception, another exception occurred:\n",
      "\n",
      "Traceback (most recent call last):\n",
      "  File \"C:\\Users\\Hameez\\.conda\\envs\\gpu_tf\\lib\\site-packages\\IPython\\core\\ultratb.py\", line 1170, in get_records\n",
      "    return _fixed_getinnerframes(etb, number_of_lines_of_context, tb_offset)\n",
      "  File \"C:\\Users\\Hameez\\.conda\\envs\\gpu_tf\\lib\\site-packages\\IPython\\core\\ultratb.py\", line 316, in wrapped\n",
      "    return f(*args, **kwargs)\n",
      "  File \"C:\\Users\\Hameez\\.conda\\envs\\gpu_tf\\lib\\site-packages\\IPython\\core\\ultratb.py\", line 350, in _fixed_getinnerframes\n",
      "    records = fix_frame_records_filenames(inspect.getinnerframes(etb, context))\n",
      "  File \"C:\\Users\\Hameez\\.conda\\envs\\gpu_tf\\lib\\inspect.py\", line 1502, in getinnerframes\n",
      "    frameinfo = (tb.tb_frame,) + getframeinfo(tb, context)\n",
      "  File \"C:\\Users\\Hameez\\.conda\\envs\\gpu_tf\\lib\\inspect.py\", line 1460, in getframeinfo\n",
      "    filename = getsourcefile(frame) or getfile(frame)\n",
      "  File \"C:\\Users\\Hameez\\.conda\\envs\\gpu_tf\\lib\\inspect.py\", line 696, in getsourcefile\n",
      "    if getattr(getmodule(object, filename), '__loader__', None) is not None:\n",
      "  File \"C:\\Users\\Hameez\\.conda\\envs\\gpu_tf\\lib\\inspect.py\", line 733, in getmodule\n",
      "    if ismodule(module) and hasattr(module, '__file__'):\n",
      "  File \"C:\\Users\\Hameez\\.conda\\envs\\gpu_tf\\lib\\site-packages\\tensorflow\\__init__.py\", line 50, in __getattr__\n",
      "    module = self._load()\n",
      "  File \"C:\\Users\\Hameez\\.conda\\envs\\gpu_tf\\lib\\site-packages\\tensorflow\\__init__.py\", line 44, in _load\n",
      "    module = _importlib.import_module(self.__name__)\n",
      "  File \"C:\\Users\\Hameez\\.conda\\envs\\gpu_tf\\lib\\importlib\\__init__.py\", line 127, in import_module\n",
      "    return _bootstrap._gcd_import(name[level:], package, level)\n",
      "  File \"<frozen importlib._bootstrap>\", line 1006, in _gcd_import\n",
      "  File \"<frozen importlib._bootstrap>\", line 983, in _find_and_load\n",
      "  File \"<frozen importlib._bootstrap>\", line 965, in _find_and_load_unlocked\n",
      "ModuleNotFoundError: No module named 'tensorflow_core.estimator'\n",
      "Traceback (most recent call last):\n",
      "  File \"C:\\Users\\Hameez\\.conda\\envs\\gpu_tf\\lib\\site-packages\\IPython\\core\\interactiveshell.py\", line 3418, in run_code\n",
      "    exec(code_obj, self.user_global_ns, self.user_ns)\n",
      "  File \"<ipython-input-1-e3e6886b4170>\", line 5, in <module>\n",
      "    from tensorflow.keras.applications.MobileNet import preprocess_input, decode_predictions\n",
      "ModuleNotFoundError: No module named 'tensorflow.keras.applications.MobileNet'\n",
      "\n",
      "During handling of the above exception, another exception occurred:\n",
      "\n",
      "Traceback (most recent call last):\n",
      "  File \"C:\\Users\\Hameez\\.conda\\envs\\gpu_tf\\lib\\site-packages\\IPython\\core\\interactiveshell.py\", line 2045, in showtraceback\n",
      "    stb = value._render_traceback_()\n",
      "AttributeError: 'ModuleNotFoundError' object has no attribute '_render_traceback_'\n",
      "\n",
      "During handling of the above exception, another exception occurred:\n",
      "\n",
      "Traceback (most recent call last):\n",
      "  File \"C:\\Users\\Hameez\\.conda\\envs\\gpu_tf\\lib\\site-packages\\IPython\\core\\interactiveshell.py\", line 3338, in run_ast_nodes\n",
      "    if (await self.run_code(code, result,  async_=asy)):\n",
      "  File \"C:\\Users\\Hameez\\.conda\\envs\\gpu_tf\\lib\\site-packages\\IPython\\core\\interactiveshell.py\", line 3435, in run_code\n",
      "    self.showtraceback(running_compiled_code=True)\n",
      "  File \"C:\\Users\\Hameez\\.conda\\envs\\gpu_tf\\lib\\site-packages\\IPython\\core\\interactiveshell.py\", line 2048, in showtraceback\n",
      "    value, tb, tb_offset=tb_offset)\n",
      "  File \"C:\\Users\\Hameez\\.conda\\envs\\gpu_tf\\lib\\site-packages\\IPython\\core\\ultratb.py\", line 1437, in structured_traceback\n",
      "    self, etype, value, tb, tb_offset, number_of_lines_of_context)\n",
      "  File \"C:\\Users\\Hameez\\.conda\\envs\\gpu_tf\\lib\\site-packages\\IPython\\core\\ultratb.py\", line 1337, in structured_traceback\n",
      "    self, etype, value, tb, tb_offset, number_of_lines_of_context\n",
      "  File \"C:\\Users\\Hameez\\.conda\\envs\\gpu_tf\\lib\\site-packages\\IPython\\core\\ultratb.py\", line 1194, in structured_traceback\n",
      "    tb_offset)\n",
      "  File \"C:\\Users\\Hameez\\.conda\\envs\\gpu_tf\\lib\\site-packages\\IPython\\core\\ultratb.py\", line 1151, in format_exception_as_a_whole\n",
      "    last_unique, recursion_repeat = find_recursion(orig_etype, evalue, records)\n",
      "  File \"C:\\Users\\Hameez\\.conda\\envs\\gpu_tf\\lib\\site-packages\\IPython\\core\\ultratb.py\", line 451, in find_recursion\n",
      "    return len(records), 0\n",
      "TypeError: object of type 'NoneType' has no len()\n",
      "\n",
      "During handling of the above exception, another exception occurred:\n",
      "\n",
      "Traceback (most recent call last):\n",
      "  File \"C:\\Users\\Hameez\\.conda\\envs\\gpu_tf\\lib\\site-packages\\IPython\\core\\interactiveshell.py\", line 2045, in showtraceback\n",
      "    stb = value._render_traceback_()\n",
      "AttributeError: 'TypeError' object has no attribute '_render_traceback_'\n",
      "\n",
      "During handling of the above exception, another exception occurred:\n",
      "\n",
      "Traceback (most recent call last):\n",
      "  File \"C:\\Users\\Hameez\\.conda\\envs\\gpu_tf\\lib\\site-packages\\IPython\\core\\ultratb.py\", line 1170, in get_records\n",
      "    return _fixed_getinnerframes(etb, number_of_lines_of_context, tb_offset)\n",
      "  File \"C:\\Users\\Hameez\\.conda\\envs\\gpu_tf\\lib\\site-packages\\IPython\\core\\ultratb.py\", line 316, in wrapped\n",
      "    return f(*args, **kwargs)\n",
      "  File \"C:\\Users\\Hameez\\.conda\\envs\\gpu_tf\\lib\\site-packages\\IPython\\core\\ultratb.py\", line 350, in _fixed_getinnerframes\n",
      "    records = fix_frame_records_filenames(inspect.getinnerframes(etb, context))\n",
      "  File \"C:\\Users\\Hameez\\.conda\\envs\\gpu_tf\\lib\\inspect.py\", line 1502, in getinnerframes\n",
      "    frameinfo = (tb.tb_frame,) + getframeinfo(tb, context)\n",
      "  File \"C:\\Users\\Hameez\\.conda\\envs\\gpu_tf\\lib\\inspect.py\", line 1460, in getframeinfo\n",
      "    filename = getsourcefile(frame) or getfile(frame)\n",
      "  File \"C:\\Users\\Hameez\\.conda\\envs\\gpu_tf\\lib\\inspect.py\", line 696, in getsourcefile\n",
      "    if getattr(getmodule(object, filename), '__loader__', None) is not None:\n",
      "  File \"C:\\Users\\Hameez\\.conda\\envs\\gpu_tf\\lib\\inspect.py\", line 733, in getmodule\n",
      "    if ismodule(module) and hasattr(module, '__file__'):\n",
      "  File \"C:\\Users\\Hameez\\.conda\\envs\\gpu_tf\\lib\\site-packages\\tensorflow\\__init__.py\", line 50, in __getattr__\n",
      "    module = self._load()\n",
      "  File \"C:\\Users\\Hameez\\.conda\\envs\\gpu_tf\\lib\\site-packages\\tensorflow\\__init__.py\", line 44, in _load\n",
      "    module = _importlib.import_module(self.__name__)\n",
      "  File \"C:\\Users\\Hameez\\.conda\\envs\\gpu_tf\\lib\\importlib\\__init__.py\", line 127, in import_module\n",
      "    return _bootstrap._gcd_import(name[level:], package, level)\n",
      "  File \"<frozen importlib._bootstrap>\", line 1006, in _gcd_import\n",
      "  File \"<frozen importlib._bootstrap>\", line 983, in _find_and_load\n",
      "  File \"<frozen importlib._bootstrap>\", line 965, in _find_and_load_unlocked\n",
      "ModuleNotFoundError: No module named 'tensorflow_core.estimator'\n",
      "Traceback (most recent call last):\n",
      "  File \"C:\\Users\\Hameez\\.conda\\envs\\gpu_tf\\lib\\site-packages\\IPython\\core\\interactiveshell.py\", line 3418, in run_code\n",
      "    exec(code_obj, self.user_global_ns, self.user_ns)\n",
      "  File \"<ipython-input-1-e3e6886b4170>\", line 5, in <module>\n",
      "    from tensorflow.keras.applications.MobileNet import preprocess_input, decode_predictions\n",
      "ModuleNotFoundError: No module named 'tensorflow.keras.applications.MobileNet'\n",
      "\n",
      "During handling of the above exception, another exception occurred:\n",
      "\n",
      "Traceback (most recent call last):\n",
      "  File \"C:\\Users\\Hameez\\.conda\\envs\\gpu_tf\\lib\\site-packages\\IPython\\core\\interactiveshell.py\", line 2045, in showtraceback\n",
      "    stb = value._render_traceback_()\n",
      "AttributeError: 'ModuleNotFoundError' object has no attribute '_render_traceback_'\n",
      "\n",
      "During handling of the above exception, another exception occurred:\n",
      "\n",
      "Traceback (most recent call last):\n",
      "  File \"C:\\Users\\Hameez\\.conda\\envs\\gpu_tf\\lib\\site-packages\\IPython\\core\\interactiveshell.py\", line 3338, in run_ast_nodes\n",
      "    if (await self.run_code(code, result,  async_=asy)):\n",
      "  File \"C:\\Users\\Hameez\\.conda\\envs\\gpu_tf\\lib\\site-packages\\IPython\\core\\interactiveshell.py\", line 3435, in run_code\n",
      "    self.showtraceback(running_compiled_code=True)\n",
      "  File \"C:\\Users\\Hameez\\.conda\\envs\\gpu_tf\\lib\\site-packages\\IPython\\core\\interactiveshell.py\", line 2048, in showtraceback\n",
      "    value, tb, tb_offset=tb_offset)\n",
      "  File \"C:\\Users\\Hameez\\.conda\\envs\\gpu_tf\\lib\\site-packages\\IPython\\core\\ultratb.py\", line 1437, in structured_traceback\n",
      "    self, etype, value, tb, tb_offset, number_of_lines_of_context)\n",
      "  File \"C:\\Users\\Hameez\\.conda\\envs\\gpu_tf\\lib\\site-packages\\IPython\\core\\ultratb.py\", line 1337, in structured_traceback\n",
      "    self, etype, value, tb, tb_offset, number_of_lines_of_context\n",
      "  File \"C:\\Users\\Hameez\\.conda\\envs\\gpu_tf\\lib\\site-packages\\IPython\\core\\ultratb.py\", line 1194, in structured_traceback\n",
      "    tb_offset)\n",
      "  File \"C:\\Users\\Hameez\\.conda\\envs\\gpu_tf\\lib\\site-packages\\IPython\\core\\ultratb.py\", line 1151, in format_exception_as_a_whole\n",
      "    last_unique, recursion_repeat = find_recursion(orig_etype, evalue, records)\n",
      "  File \"C:\\Users\\Hameez\\.conda\\envs\\gpu_tf\\lib\\site-packages\\IPython\\core\\ultratb.py\", line 451, in find_recursion\n",
      "    return len(records), 0\n",
      "TypeError: object of type 'NoneType' has no len()\n",
      "\n",
      "During handling of the above exception, another exception occurred:\n",
      "\n",
      "Traceback (most recent call last):\n",
      "  File \"C:\\Users\\Hameez\\.conda\\envs\\gpu_tf\\lib\\site-packages\\IPython\\core\\interactiveshell.py\", line 2045, in showtraceback\n",
      "    stb = value._render_traceback_()\n",
      "AttributeError: 'TypeError' object has no attribute '_render_traceback_'\n",
      "\n",
      "During handling of the above exception, another exception occurred:\n",
      "\n",
      "Traceback (most recent call last):\n",
      "  File \"C:\\Users\\Hameez\\.conda\\envs\\gpu_tf\\lib\\site-packages\\IPython\\core\\interactiveshell.py\", line 2923, in _run_cell\n",
      "    return runner(coro)\n",
      "  File \"C:\\Users\\Hameez\\.conda\\envs\\gpu_tf\\lib\\site-packages\\IPython\\core\\async_helpers.py\", line 68, in _pseudo_sync_runner\n",
      "    coro.send(None)\n",
      "  File \"C:\\Users\\Hameez\\.conda\\envs\\gpu_tf\\lib\\site-packages\\IPython\\core\\interactiveshell.py\", line 3147, in run_cell_async\n",
      "    interactivity=interactivity, compiler=compiler, result=result)\n",
      "  File \"C:\\Users\\Hameez\\.conda\\envs\\gpu_tf\\lib\\site-packages\\IPython\\core\\interactiveshell.py\", line 3357, in run_ast_nodes\n",
      "    self.showtraceback()\n",
      "  File \"C:\\Users\\Hameez\\.conda\\envs\\gpu_tf\\lib\\site-packages\\IPython\\core\\interactiveshell.py\", line 2048, in showtraceback\n",
      "    value, tb, tb_offset=tb_offset)\n",
      "  File \"C:\\Users\\Hameez\\.conda\\envs\\gpu_tf\\lib\\site-packages\\IPython\\core\\ultratb.py\", line 1437, in structured_traceback\n",
      "    self, etype, value, tb, tb_offset, number_of_lines_of_context)\n",
      "  File \"C:\\Users\\Hameez\\.conda\\envs\\gpu_tf\\lib\\site-packages\\IPython\\core\\ultratb.py\", line 1337, in structured_traceback\n",
      "    self, etype, value, tb, tb_offset, number_of_lines_of_context\n",
      "  File \"C:\\Users\\Hameez\\.conda\\envs\\gpu_tf\\lib\\site-packages\\IPython\\core\\ultratb.py\", line 1212, in structured_traceback\n",
      "    chained_exceptions_tb_offset)\n",
      "  File \"C:\\Users\\Hameez\\.conda\\envs\\gpu_tf\\lib\\site-packages\\IPython\\core\\ultratb.py\", line 1151, in format_exception_as_a_whole\n",
      "    last_unique, recursion_repeat = find_recursion(orig_etype, evalue, records)\n",
      "  File \"C:\\Users\\Hameez\\.conda\\envs\\gpu_tf\\lib\\site-packages\\IPython\\core\\ultratb.py\", line 451, in find_recursion\n",
      "    return len(records), 0\n",
      "TypeError: object of type 'NoneType' has no len()\n",
      "\n",
      "During handling of the above exception, another exception occurred:\n",
      "\n",
      "Traceback (most recent call last):\n",
      "  File \"C:\\Users\\Hameez\\.conda\\envs\\gpu_tf\\lib\\site-packages\\IPython\\core\\interactiveshell.py\", line 2045, in showtraceback\n",
      "    stb = value._render_traceback_()\n",
      "AttributeError: 'TypeError' object has no attribute '_render_traceback_'\n",
      "\n",
      "During handling of the above exception, another exception occurred:\n",
      "\n",
      "Traceback (most recent call last):\n",
      "  File \"C:\\Users\\Hameez\\.conda\\envs\\gpu_tf\\lib\\site-packages\\IPython\\core\\ultratb.py\", line 1170, in get_records\n",
      "    return _fixed_getinnerframes(etb, number_of_lines_of_context, tb_offset)\n",
      "  File \"C:\\Users\\Hameez\\.conda\\envs\\gpu_tf\\lib\\site-packages\\IPython\\core\\ultratb.py\", line 316, in wrapped\n",
      "    return f(*args, **kwargs)\n",
      "  File \"C:\\Users\\Hameez\\.conda\\envs\\gpu_tf\\lib\\site-packages\\IPython\\core\\ultratb.py\", line 350, in _fixed_getinnerframes\n",
      "    records = fix_frame_records_filenames(inspect.getinnerframes(etb, context))\n",
      "  File \"C:\\Users\\Hameez\\.conda\\envs\\gpu_tf\\lib\\inspect.py\", line 1502, in getinnerframes\n",
      "    frameinfo = (tb.tb_frame,) + getframeinfo(tb, context)\n",
      "  File \"C:\\Users\\Hameez\\.conda\\envs\\gpu_tf\\lib\\inspect.py\", line 1460, in getframeinfo\n",
      "    filename = getsourcefile(frame) or getfile(frame)\n",
      "  File \"C:\\Users\\Hameez\\.conda\\envs\\gpu_tf\\lib\\inspect.py\", line 696, in getsourcefile\n",
      "    if getattr(getmodule(object, filename), '__loader__', None) is not None:\n",
      "  File \"C:\\Users\\Hameez\\.conda\\envs\\gpu_tf\\lib\\inspect.py\", line 733, in getmodule\n",
      "    if ismodule(module) and hasattr(module, '__file__'):\n",
      "  File \"C:\\Users\\Hameez\\.conda\\envs\\gpu_tf\\lib\\site-packages\\tensorflow\\__init__.py\", line 50, in __getattr__\n",
      "    module = self._load()\n",
      "  File \"C:\\Users\\Hameez\\.conda\\envs\\gpu_tf\\lib\\site-packages\\tensorflow\\__init__.py\", line 44, in _load\n",
      "    module = _importlib.import_module(self.__name__)\n",
      "  File \"C:\\Users\\Hameez\\.conda\\envs\\gpu_tf\\lib\\importlib\\__init__.py\", line 127, in import_module\n",
      "    return _bootstrap._gcd_import(name[level:], package, level)\n",
      "  File \"<frozen importlib._bootstrap>\", line 1006, in _gcd_import\n",
      "  File \"<frozen importlib._bootstrap>\", line 983, in _find_and_load\n",
      "  File \"<frozen importlib._bootstrap>\", line 965, in _find_and_load_unlocked\n",
      "ModuleNotFoundError: No module named 'tensorflow_core.estimator'\n"
     ]
    }
   ],
   "source": [
    "from tensorflow.keras.preprocessing.image import ImageDataGenerator, img_to_array, array_to_img\n",
    "from tensorflow.keras.preprocessing import image\n",
    "from tensorflow import keras\n",
    "import tensorflow as tf\n",
    "from tensorflow.keras.applications.MobileNet import preprocess_input, decode_predictions\n",
    "\n",
    "import matplotlib.pyplot as plt\n",
    "import numpy as np\n",
    "import pandas as pd\n",
    "import os\n",
    "from scipy import misc, ndimage\n",
    "import glob\n",
    "import matplotlib.image as mpimg\n",
    "import cv2\n",
    "\n",
    "import gradio as gr\n",
    "\n",
    "\n",
    "#from transform_image_data import centre_crop\n",
    "\n",
    "%matplotlib inline"
   ]
  },
  {
   "cell_type": "code",
   "execution_count": null,
   "metadata": {},
   "outputs": [],
   "source": [
    "model_path = 'Saved Models/Good Models/gs_mcl_v1.2C_100ep.h5'"
   ]
  },
  {
   "cell_type": "code",
   "execution_count": null,
   "metadata": {},
   "outputs": [],
   "source": [
    "model = tf.keras.models.load_model(model_path)\n",
    "model.summary()"
   ]
  },
  {
   "cell_type": "code",
   "execution_count": null,
   "metadata": {},
   "outputs": [],
   "source": [
    "unsean_stone_path = \"C:/Users/Hameez/.conda/envs/gemstone_dataset/Data/Unseen/citrine.jpg\"\n",
    "img = image.load_img(unsean_stone_path, target_size=(254, 254))\n",
    "\n",
    "x = image.img_to_array(img)\n",
    "x = np.expand_dims(x, axis=0)\n",
    "#x = preprocess_input(x)\n",
    "print(os.path.basename(unsean_stone_path))\n",
    "img"
   ]
  },
  {
   "cell_type": "code",
   "execution_count": null,
   "metadata": {},
   "outputs": [],
   "source": [
    "pred = model.predict(x)"
   ]
  },
  {
   "cell_type": "code",
   "execution_count": null,
   "metadata": {},
   "outputs": [],
   "source": []
  }
 ],
 "metadata": {
  "kernelspec": {
   "display_name": "gpu_tf",
   "language": "python",
   "name": "gpu_tf"
  },
  "language_info": {
   "codemirror_mode": {
    "name": "ipython",
    "version": 3
   },
   "file_extension": ".py",
   "mimetype": "text/x-python",
   "name": "python",
   "nbconvert_exporter": "python",
   "pygments_lexer": "ipython3",
   "version": "3.7.9"
  }
 },
 "nbformat": 4,
 "nbformat_minor": 4
}
