{
 "cells": [
  {
   "cell_type": "code",
   "execution_count": 1,
   "metadata": {},
   "outputs": [],
   "source": [
    "from tensorflow.keras.preprocessing.image import ImageDataGenerator, img_to_array, array_to_img\n",
    "from tensorflow.keras.preprocessing import image\n",
    "from tensorflow.keras.optimizers import RMSprop, SGD\n",
    "import tensorflow as tf\n",
    "\n",
    "import matplotlib.pyplot as plt\n",
    "import numpy as np\n",
    "import pandas as pd\n",
    "import os\n",
    "from scipy import misc, ndimage\n",
    "import glob\n",
    "import matplotlib.image as mpimg\n",
    "import cv2\n",
    "\n",
    "#from transform_image_data import centre_crop\n",
    "\n",
    "%matplotlib inline"
   ]
  },
  {
   "cell_type": "code",
   "execution_count": 2,
   "metadata": {},
   "outputs": [
    {
     "name": "stdout",
     "output_type": "stream",
     "text": [
      "Default GPU Device:/device:GPU:0\n",
      "2.1.0\n"
     ]
    }
   ],
   "source": [
    "if tf.test.gpu_device_name(): \n",
    "    print('Default GPU Device:{}'.format(tf.test.gpu_device_name()))\n",
    "else:\n",
    "    print(\"Please install GPU version of TF\")\n",
    "print(tf.__version__)"
   ]
  },
  {
   "cell_type": "code",
   "execution_count": 3,
   "metadata": {},
   "outputs": [
    {
     "name": "stdout",
     "output_type": "stream",
     "text": [
      "Found 2857 images belonging to 87 classes.\n",
      "Found 363 images belonging to 87 classes.\n"
     ]
    }
   ],
   "source": [
    "#import Data\n",
    "\n",
    "train_folder = \"C:/Users/Hameez/.conda/envs/gemstone_dataset/Data/Cropped/Train/\"\n",
    "test_folder = \"C:/Users/Hameez/.conda/envs/gemstone_dataset/Data/Test/\"\n",
    "\n",
    "\n",
    "# img = image.load_img(train_folder+\"/Alexandrite/alexandrite_2.jpg\")\n",
    "# # plt.imshow(img)\n",
    "# # plt.show()\n",
    "# print(cv2.imread(\"Data/Train/Alexandrite/alexandrite_24.jpg\").shape)\n",
    "\n",
    "#------------Image augmentation for train images----------------------------------#\n",
    "train = ImageDataGenerator(rescale=1/255, shear_range=0.5,\n",
    "                                  rotation_range=90, channel_shift_range=2.5)\n",
    "#---------------------------------------------------------------------------#\n",
    "\n",
    "test = ImageDataGenerator(rescale=1/255)\n",
    "\n",
    "im_height = im_width = 224\n",
    "\n",
    "train_data = train.flow_from_directory(train_folder,\n",
    "                                       target_size=(im_height,im_width),\n",
    "                                       class_mode='categorical')\n",
    "test_data = test.flow_from_directory(test_folder,\n",
    "                                       target_size=(im_height,im_width),\n",
    "                                       class_mode='categorical')\n",
    "\n",
    "\n",
    "\n"
   ]
  },
  {
   "cell_type": "code",
   "execution_count": 4,
   "metadata": {},
   "outputs": [],
   "source": [
    "# images = []\n",
    "# stone = 'Ametrine'\n",
    "# for img_path in glob.glob(train_folder+stone+'/*.jpg'):\n",
    "#     images.append(mpimg.imread(img_path))\n",
    "\n",
    "# plt.figure(figsize=(25,25))\n",
    "# columns = 4\n",
    "# for i, image in enumerate(images):\n",
    "#     if i > 7:\n",
    "#         break\n",
    "#     else:\n",
    "#         plt.subplot(len(images) / columns + 1, columns, i + 1)\n",
    "#         plt.title(stone)\n",
    "#         plt.imshow(image)\n",
    "        "
   ]
  },
  {
   "cell_type": "code",
   "execution_count": 5,
   "metadata": {},
   "outputs": [],
   "source": [
    "# test_augment = ImageDataGenerator(rescale=1/255, zoom_range=2.0, shear_range=0.5,\n",
    "#                                   rotation_range=60, channel_shift_range=2.5)#, ,)\n",
    "# img = image.load_img(train_folder+\"/Chalcedony/chalcedony_5.jpg\")\n",
    "# plt.imshow(img)\n",
    "\n"
   ]
  },
  {
   "cell_type": "code",
   "execution_count": 6,
   "metadata": {},
   "outputs": [],
   "source": [
    "\n",
    "# x = img_to_array(x)\n",
    "\n",
    "# x = x.reshape((1,) + x.shape)\n",
    "# # x.shape\n",
    "\n",
    "# i = 0\n",
    "# for batch in test_augment.flow(x, batch_size=1,\n",
    "#                               save_to_dir='Augmented', save_prefix='alexandrite',\n",
    "#                                save_format='jpeg',):\n",
    "#     i += 1\n",
    "#     if i > 20:\n",
    "#         break"
   ]
  },
  {
   "cell_type": "markdown",
   "metadata": {},
   "source": [
    "### CNN Model "
   ]
  },
  {
   "cell_type": "code",
   "execution_count": 7,
   "metadata": {},
   "outputs": [
    {
     "name": "stdout",
     "output_type": "stream",
     "text": [
      "Model: \"sequential\"\n",
      "_________________________________________________________________\n",
      "Layer (type)                 Output Shape              Param #   \n",
      "=================================================================\n",
      "conv2d (Conv2D)              (None, 222, 222, 32)      896       \n",
      "_________________________________________________________________\n",
      "batch_normalization (BatchNo (None, 222, 222, 32)      128       \n",
      "_________________________________________________________________\n",
      "max_pooling2d (MaxPooling2D) (None, 111, 111, 32)      0         \n",
      "_________________________________________________________________\n",
      "conv2d_1 (Conv2D)            (None, 109, 109, 64)      18496     \n",
      "_________________________________________________________________\n",
      "batch_normalization_1 (Batch (None, 109, 109, 64)      256       \n",
      "_________________________________________________________________\n",
      "max_pooling2d_1 (MaxPooling2 (None, 54, 54, 64)        0         \n",
      "_________________________________________________________________\n",
      "conv2d_2 (Conv2D)            (None, 52, 52, 128)       73856     \n",
      "_________________________________________________________________\n",
      "batch_normalization_2 (Batch (None, 52, 52, 128)       512       \n",
      "_________________________________________________________________\n",
      "max_pooling2d_2 (MaxPooling2 (None, 26, 26, 128)       0         \n",
      "_________________________________________________________________\n",
      "conv2d_3 (Conv2D)            (None, 24, 24, 256)       295168    \n",
      "_________________________________________________________________\n",
      "batch_normalization_3 (Batch (None, 24, 24, 256)       1024      \n",
      "_________________________________________________________________\n",
      "max_pooling2d_3 (MaxPooling2 (None, 12, 12, 256)       0         \n",
      "_________________________________________________________________\n",
      "flatten (Flatten)            (None, 36864)             0         \n",
      "_________________________________________________________________\n",
      "dense (Dense)                (None, 512)               18874880  \n",
      "_________________________________________________________________\n",
      "dropout (Dropout)            (None, 512)               0         \n",
      "_________________________________________________________________\n",
      "dense_1 (Dense)              (None, 512)               262656    \n",
      "_________________________________________________________________\n",
      "dropout_1 (Dropout)          (None, 512)               0         \n",
      "_________________________________________________________________\n",
      "dense_2 (Dense)              (None, 512)               262656    \n",
      "_________________________________________________________________\n",
      "dropout_2 (Dropout)          (None, 512)               0         \n",
      "_________________________________________________________________\n",
      "dense_3 (Dense)              (None, 87)                44631     \n",
      "=================================================================\n",
      "Total params: 19,835,159\n",
      "Trainable params: 19,834,199\n",
      "Non-trainable params: 960\n",
      "_________________________________________________________________\n"
     ]
    }
   ],
   "source": [
    "\n",
    "cnn_model = tf.keras.models.Sequential([tf.keras.layers.Conv2D(32,(3,3),activation='relu',input_shape=(im_height,im_width,3)),\n",
    "                                        tf.keras.layers.BatchNormalization(),\n",
    "                                        tf.keras.layers.MaxPool2D(2,2),\n",
    "                                        #\n",
    "                                        tf.keras.layers.Conv2D(64,(3,3),activation='relu'),\n",
    "                                        tf.keras.layers.BatchNormalization(),\n",
    "                                        tf.keras.layers.MaxPool2D(2,2),\n",
    "                                        \n",
    "                                        tf.keras.layers.Conv2D(128,(3,3),activation='relu'),\n",
    "                                        tf.keras.layers.BatchNormalization(),\n",
    "                                        tf.keras.layers.MaxPool2D(2,2),\n",
    "                                        \n",
    "                                        tf.keras.layers.Conv2D(256,(3,3),activation='relu'),\n",
    "                                        tf.keras.layers.BatchNormalization(),\n",
    "                                        tf.keras.layers.MaxPool2D(2,2),\n",
    "                                        #\n",
    "#                                         tf.keras.layers.Conv2D(256,(3,3),activation='relu'),\n",
    "#                                         tf.keras.layers.MaxPool2D(2,2),\n",
    "                                        #\n",
    "                                        tf.keras.layers.Flatten(),\n",
    "                                        ##\n",
    "                                        tf.keras.layers.Dense(512, activation='relu'),\n",
    "                                        tf.keras.layers.Dropout(0.1),\n",
    "                                        #\n",
    "                                        tf.keras.layers.Dense(512, activation='relu'),\n",
    "                                        tf.keras.layers.Dropout(0.1),\n",
    "                                        #\n",
    "                                        tf.keras.layers.Dense(512, activation='relu'),\n",
    "                                        tf.keras.layers.Dropout(0.1),\n",
    "                                        #\n",
    "                                        tf.keras.layers.Dense(87, activation='softmax')\n",
    "                                        ])\n",
    "cnn_model.summary()\n"
   ]
  },
  {
   "cell_type": "code",
   "execution_count": null,
   "metadata": {},
   "outputs": [
    {
     "name": "stdout",
     "output_type": "stream",
     "text": [
      "WARNING:tensorflow:From <ipython-input-8-89c75f9f1d70>:6: Model.fit_generator (from tensorflow.python.keras.engine.training) is deprecated and will be removed in a future version.\n",
      "Instructions for updating:\n",
      "Please use Model.fit, which supports generators.\n",
      "WARNING:tensorflow:sample_weight modes were coerced from\n",
      "  ...\n",
      "    to  \n",
      "  ['...']\n",
      "WARNING:tensorflow:sample_weight modes were coerced from\n",
      "  ...\n",
      "    to  \n",
      "  ['...']\n",
      "Train for 90 steps, validate for 12 steps\n",
      "Epoch 1/50\n",
      "90/90 [==============================] - 78s 871ms/step - loss: 3.6270 - accuracy: 0.1481 - val_loss: 4.6383 - val_accuracy: 0.0138\n",
      "Epoch 2/50\n",
      "90/90 [==============================] - 72s 801ms/step - loss: 2.5934 - accuracy: 0.2930 - val_loss: 5.1393 - val_accuracy: 0.0220\n",
      "Epoch 3/50\n",
      "90/90 [==============================] - 167s 2s/step - loss: 2.2237 - accuracy: 0.3626 - val_loss: 5.3063 - val_accuracy: 0.0275\n",
      "Epoch 4/50\n",
      "90/90 [==============================] - 100s 1s/step - loss: 2.0158 - accuracy: 0.4106 - val_loss: 4.2428 - val_accuracy: 0.0579\n",
      "Epoch 5/50\n",
      "90/90 [==============================] - 140s 2s/step - loss: 1.8229 - accuracy: 0.4491 - val_loss: 3.3015 - val_accuracy: 0.1570\n",
      "Epoch 6/50\n",
      "90/90 [==============================] - 124s 1s/step - loss: 1.6960 - accuracy: 0.4844 - val_loss: 3.4187 - val_accuracy: 0.1901\n",
      "Epoch 7/50\n",
      "90/90 [==============================] - 139s 2s/step - loss: 1.5429 - accuracy: 0.5264 - val_loss: 4.1144 - val_accuracy: 0.1185\n",
      "Epoch 8/50\n",
      "90/90 [==============================] - 142s 2s/step - loss: 1.4634 - accuracy: 0.5432 - val_loss: 4.2766 - val_accuracy: 0.1074\n",
      "Epoch 9/50\n",
      "90/90 [==============================] - 119s 1s/step - loss: 1.3107 - accuracy: 0.5894 - val_loss: 3.7415 - val_accuracy: 0.2204\n",
      "Epoch 10/50\n",
      "90/90 [==============================] - 152s 2s/step - loss: 1.2434 - accuracy: 0.6111 - val_loss: 3.7046 - val_accuracy: 0.2094\n",
      "Epoch 11/50\n",
      "90/90 [==============================] - 128s 1s/step - loss: 1.1718 - accuracy: 0.6167 - val_loss: 3.7014 - val_accuracy: 0.2094\n",
      "Epoch 12/50\n",
      "90/90 [==============================] - 149s 2s/step - loss: 1.1050 - accuracy: 0.6370 - val_loss: 3.8082 - val_accuracy: 0.1846\n",
      "Epoch 13/50\n",
      "90/90 [==============================] - 137s 2s/step - loss: 1.0163 - accuracy: 0.6664 - val_loss: 3.8734 - val_accuracy: 0.2176\n",
      "Epoch 14/50\n",
      "90/90 [==============================] - 126s 1s/step - loss: 0.9843 - accuracy: 0.6783 - val_loss: 4.0740 - val_accuracy: 0.1598\n",
      "Epoch 15/50\n",
      "90/90 [==============================] - 116s 1s/step - loss: 0.9202 - accuracy: 0.6906 - val_loss: 4.1225 - val_accuracy: 0.1791\n",
      "Epoch 16/50\n",
      "90/90 [==============================] - 187s 2s/step - loss: 0.8735 - accuracy: 0.7102 - val_loss: 4.3792 - val_accuracy: 0.1791\n",
      "Epoch 17/50\n",
      "90/90 [==============================] - 101s 1s/step - loss: 0.8189 - accuracy: 0.7277 - val_loss: 4.0191 - val_accuracy: 0.2259\n",
      "Epoch 18/50\n",
      "90/90 [==============================] - 200s 2s/step - loss: 0.7711 - accuracy: 0.7308 - val_loss: 4.5655 - val_accuracy: 0.1736\n",
      "Epoch 19/50\n",
      "90/90 [==============================] - 69s 766ms/step - loss: 0.6874 - accuracy: 0.7662 - val_loss: 4.6987 - val_accuracy: 0.1708\n",
      "Epoch 20/50\n",
      "90/90 [==============================] - 205s 2s/step - loss: 0.6557 - accuracy: 0.7854 - val_loss: 4.4852 - val_accuracy: 0.1901\n",
      "Epoch 21/50\n",
      "90/90 [==============================] - 68s 754ms/step - loss: 0.6469 - accuracy: 0.7774 - val_loss: 4.4824 - val_accuracy: 0.1983\n",
      "Epoch 22/50\n",
      "90/90 [==============================] - 189s 2s/step - loss: 0.5901 - accuracy: 0.7987 - val_loss: 4.3647 - val_accuracy: 0.1901\n",
      "Epoch 23/50\n",
      "90/90 [==============================] - 73s 806ms/step - loss: 0.5633 - accuracy: 0.8110 - val_loss: 4.4346 - val_accuracy: 0.1956\n",
      "Epoch 24/50\n",
      "90/90 [==============================] - 205s 2s/step - loss: 0.4934 - accuracy: 0.8365 - val_loss: 4.5447 - val_accuracy: 0.2039\n",
      "Epoch 25/50\n",
      "90/90 [==============================] - 74s 820ms/step - loss: 0.4994 - accuracy: 0.8302 - val_loss: 4.4091 - val_accuracy: 0.1983\n",
      "Epoch 26/50\n",
      "90/90 [==============================] - 212s 2s/step - loss: 0.4567 - accuracy: 0.8439 - val_loss: 4.9625 - val_accuracy: 0.2094\n",
      "Epoch 27/50\n",
      "90/90 [==============================] - 72s 804ms/step - loss: 0.4338 - accuracy: 0.8558 - val_loss: 5.6453 - val_accuracy: 0.1763\n",
      "Epoch 28/50\n",
      "90/90 [==============================] - 209s 2s/step - loss: 0.4228 - accuracy: 0.8558 - val_loss: 4.8274 - val_accuracy: 0.2039\n",
      "Epoch 29/50\n",
      "90/90 [==============================] - 73s 812ms/step - loss: 0.3990 - accuracy: 0.8666 - val_loss: 5.0258 - val_accuracy: 0.1983\n",
      "Epoch 30/50\n",
      "90/90 [==============================] - 209s 2s/step - loss: 0.3562 - accuracy: 0.8768 - val_loss: 5.0259 - val_accuracy: 0.2204\n",
      "Epoch 31/50\n",
      "90/90 [==============================] - 71s 793ms/step - loss: 0.3566 - accuracy: 0.8817 - val_loss: 4.6340 - val_accuracy: 0.2314\n",
      "Epoch 32/50\n",
      "90/90 [==============================] - 210s 2s/step - loss: 0.3392 - accuracy: 0.8862 - val_loss: 5.0616 - val_accuracy: 0.2039\n",
      "Epoch 33/50\n",
      "90/90 [==============================] - 72s 800ms/step - loss: 0.3347 - accuracy: 0.8894 - val_loss: 5.1051 - val_accuracy: 0.2011\n",
      "Epoch 34/50\n",
      "90/90 [==============================] - 220s 2s/step - loss: 0.2875 - accuracy: 0.9037 - val_loss: 5.5901 - val_accuracy: 0.1928\n",
      "Epoch 35/50\n",
      "90/90 [==============================] - 70s 774ms/step - loss: 0.3094 - accuracy: 0.9034 - val_loss: 5.6573 - val_accuracy: 0.1818\n",
      "Epoch 36/50\n",
      "90/90 [==============================] - 226s 3s/step - loss: 0.2911 - accuracy: 0.9058 - val_loss: 5.8505 - val_accuracy: 0.1901\n",
      "Epoch 37/50\n",
      "90/90 [==============================] - 70s 782ms/step - loss: 0.2601 - accuracy: 0.9100 - val_loss: 5.4540 - val_accuracy: 0.2121\n",
      "Epoch 38/50\n",
      "90/90 [==============================] - 202s 2s/step - loss: 0.2589 - accuracy: 0.9142 - val_loss: 5.7861 - val_accuracy: 0.1956\n",
      "Epoch 39/50\n",
      "90/90 [==============================] - 72s 800ms/step - loss: 0.2634 - accuracy: 0.9118 - val_loss: 5.4244 - val_accuracy: 0.2121\n",
      "Epoch 40/50\n",
      "90/90 [==============================] - 215s 2s/step - loss: 0.2218 - accuracy: 0.9289 - val_loss: 5.7301 - val_accuracy: 0.1983\n",
      "Epoch 41/50\n",
      "90/90 [==============================] - 72s 802ms/step - loss: 0.2162 - accuracy: 0.9261 - val_loss: 5.9033 - val_accuracy: 0.2121\n",
      "Epoch 42/50\n",
      "90/90 [==============================] - 200s 2s/step - loss: 0.2143 - accuracy: 0.9314 - val_loss: 5.7554 - val_accuracy: 0.1846\n",
      "Epoch 43/50\n",
      "90/90 [==============================] - 94s 1s/step - loss: 0.1921 - accuracy: 0.9377 - val_loss: 6.3975 - val_accuracy: 0.1680\n",
      "Epoch 44/50\n",
      "90/90 [==============================] - 166s 2s/step - loss: 0.1858 - accuracy: 0.9408 - val_loss: 5.6391 - val_accuracy: 0.2176\n",
      "Epoch 45/50\n",
      "64/90 [====================>.........] - ETA: 35s - loss: 0.1660 - accuracy: 0.9473"
     ]
    },
    {
     "name": "stderr",
     "output_type": "stream",
     "text": [
      "ERROR:root:Internal Python error in the inspect module.\n",
      "Below is the traceback from this internal error.\n",
      "\n",
      "ERROR:root:Internal Python error in the inspect module.\n",
      "Below is the traceback from this internal error.\n",
      "\n",
      "ERROR:root:Internal Python error in the inspect module.\n",
      "Below is the traceback from this internal error.\n",
      "\n"
     ]
    },
    {
     "name": "stdout",
     "output_type": "stream",
     "text": [
      "Traceback (most recent call last):\n",
      "  File \"C:\\Users\\Hameez\\.conda\\envs\\gpu_tf\\lib\\site-packages\\IPython\\core\\interactiveshell.py\", line 3418, in run_code\n",
      "    exec(code_obj, self.user_global_ns, self.user_ns)\n",
      "  File \"<ipython-input-8-89c75f9f1d70>\", line 6, in <module>\n",
      "    history = cnn_model.fit_generator(train_data, epochs=50, validation_data=test_data, verbose=1)\n",
      "  File \"C:\\Users\\Hameez\\.conda\\envs\\gpu_tf\\lib\\site-packages\\tensorflow_core\\python\\util\\deprecation.py\", line 324, in new_func\n",
      "    return func(*args, **kwargs)\n",
      "  File \"C:\\Users\\Hameez\\.conda\\envs\\gpu_tf\\lib\\site-packages\\tensorflow_core\\python\\keras\\engine\\training.py\", line 1306, in fit_generator\n",
      "    initial_epoch=initial_epoch)\n",
      "  File \"C:\\Users\\Hameez\\.conda\\envs\\gpu_tf\\lib\\site-packages\\tensorflow_core\\python\\keras\\engine\\training.py\", line 819, in fit\n",
      "    use_multiprocessing=use_multiprocessing)\n",
      "  File \"C:\\Users\\Hameez\\.conda\\envs\\gpu_tf\\lib\\site-packages\\tensorflow_core\\python\\keras\\engine\\training_v2.py\", line 342, in fit\n",
      "    total_epochs=epochs)\n",
      "  File \"C:\\Users\\Hameez\\.conda\\envs\\gpu_tf\\lib\\site-packages\\tensorflow_core\\python\\keras\\engine\\training_v2.py\", line 128, in run_one_epoch\n",
      "    batch_outs = execution_function(iterator)\n",
      "  File \"C:\\Users\\Hameez\\.conda\\envs\\gpu_tf\\lib\\site-packages\\tensorflow_core\\python\\keras\\engine\\training_v2_utils.py\", line 98, in execution_function\n",
      "    distributed_function(input_fn))\n",
      "  File \"C:\\Users\\Hameez\\.conda\\envs\\gpu_tf\\lib\\site-packages\\tensorflow_core\\python\\util\\nest.py\", line 568, in map_structure\n",
      "    structure[0], [func(*x) for x in entries],\n",
      "  File \"C:\\Users\\Hameez\\.conda\\envs\\gpu_tf\\lib\\site-packages\\tensorflow_core\\python\\util\\nest.py\", line 568, in <listcomp>\n",
      "    structure[0], [func(*x) for x in entries],\n",
      "  File \"C:\\Users\\Hameez\\.conda\\envs\\gpu_tf\\lib\\site-packages\\tensorflow_core\\python\\keras\\engine\\training_v2_utils.py\", line 130, in _non_none_constant_value\n",
      "    constant_value = tensor_util.constant_value(v)\n",
      "  File \"C:\\Users\\Hameez\\.conda\\envs\\gpu_tf\\lib\\site-packages\\tensorflow_core\\python\\framework\\tensor_util.py\", line 822, in constant_value\n",
      "    return tensor.numpy()\n",
      "  File \"C:\\Users\\Hameez\\.conda\\envs\\gpu_tf\\lib\\site-packages\\tensorflow_core\\python\\framework\\ops.py\", line 942, in numpy\n",
      "    maybe_arr = self._numpy()  # pylint: disable=protected-access\n",
      "  File \"C:\\Users\\Hameez\\.conda\\envs\\gpu_tf\\lib\\site-packages\\tensorflow_core\\python\\framework\\ops.py\", line 908, in _numpy\n",
      "    return self._numpy_internal()\n",
      "KeyboardInterrupt\n",
      "\n",
      "During handling of the above exception, another exception occurred:\n",
      "\n",
      "Traceback (most recent call last):\n",
      "  File \"C:\\Users\\Hameez\\.conda\\envs\\gpu_tf\\lib\\site-packages\\IPython\\core\\interactiveshell.py\", line 2045, in showtraceback\n",
      "    stb = value._render_traceback_()\n",
      "AttributeError: 'KeyboardInterrupt' object has no attribute '_render_traceback_'\n",
      "\n",
      "During handling of the above exception, another exception occurred:\n",
      "\n",
      "Traceback (most recent call last):\n",
      "  File \"C:\\Users\\Hameez\\.conda\\envs\\gpu_tf\\lib\\site-packages\\IPython\\core\\ultratb.py\", line 1170, in get_records\n",
      "    return _fixed_getinnerframes(etb, number_of_lines_of_context, tb_offset)\n",
      "  File \"C:\\Users\\Hameez\\.conda\\envs\\gpu_tf\\lib\\site-packages\\IPython\\core\\ultratb.py\", line 316, in wrapped\n",
      "    return f(*args, **kwargs)\n",
      "  File \"C:\\Users\\Hameez\\.conda\\envs\\gpu_tf\\lib\\site-packages\\IPython\\core\\ultratb.py\", line 350, in _fixed_getinnerframes\n",
      "    records = fix_frame_records_filenames(inspect.getinnerframes(etb, context))\n",
      "  File \"C:\\Users\\Hameez\\.conda\\envs\\gpu_tf\\lib\\inspect.py\", line 1502, in getinnerframes\n",
      "    frameinfo = (tb.tb_frame,) + getframeinfo(tb, context)\n",
      "  File \"C:\\Users\\Hameez\\.conda\\envs\\gpu_tf\\lib\\inspect.py\", line 1460, in getframeinfo\n",
      "    filename = getsourcefile(frame) or getfile(frame)\n",
      "  File \"C:\\Users\\Hameez\\.conda\\envs\\gpu_tf\\lib\\inspect.py\", line 696, in getsourcefile\n",
      "    if getattr(getmodule(object, filename), '__loader__', None) is not None:\n",
      "  File \"C:\\Users\\Hameez\\.conda\\envs\\gpu_tf\\lib\\inspect.py\", line 733, in getmodule\n",
      "    if ismodule(module) and hasattr(module, '__file__'):\n",
      "  File \"C:\\Users\\Hameez\\.conda\\envs\\gpu_tf\\lib\\site-packages\\tensorflow\\__init__.py\", line 50, in __getattr__\n",
      "    module = self._load()\n",
      "  File \"C:\\Users\\Hameez\\.conda\\envs\\gpu_tf\\lib\\site-packages\\tensorflow\\__init__.py\", line 44, in _load\n",
      "    module = _importlib.import_module(self.__name__)\n",
      "  File \"C:\\Users\\Hameez\\.conda\\envs\\gpu_tf\\lib\\importlib\\__init__.py\", line 127, in import_module\n",
      "    return _bootstrap._gcd_import(name[level:], package, level)\n",
      "  File \"<frozen importlib._bootstrap>\", line 1006, in _gcd_import\n",
      "  File \"<frozen importlib._bootstrap>\", line 983, in _find_and_load\n",
      "  File \"<frozen importlib._bootstrap>\", line 965, in _find_and_load_unlocked\n",
      "ModuleNotFoundError: No module named 'tensorflow_core.estimator'\n",
      "Traceback (most recent call last):\n",
      "  File \"C:\\Users\\Hameez\\.conda\\envs\\gpu_tf\\lib\\site-packages\\IPython\\core\\interactiveshell.py\", line 3418, in run_code\n",
      "    exec(code_obj, self.user_global_ns, self.user_ns)\n",
      "  File \"<ipython-input-8-89c75f9f1d70>\", line 6, in <module>\n",
      "    history = cnn_model.fit_generator(train_data, epochs=50, validation_data=test_data, verbose=1)\n",
      "  File \"C:\\Users\\Hameez\\.conda\\envs\\gpu_tf\\lib\\site-packages\\tensorflow_core\\python\\util\\deprecation.py\", line 324, in new_func\n",
      "    return func(*args, **kwargs)\n",
      "  File \"C:\\Users\\Hameez\\.conda\\envs\\gpu_tf\\lib\\site-packages\\tensorflow_core\\python\\keras\\engine\\training.py\", line 1306, in fit_generator\n",
      "    initial_epoch=initial_epoch)\n",
      "  File \"C:\\Users\\Hameez\\.conda\\envs\\gpu_tf\\lib\\site-packages\\tensorflow_core\\python\\keras\\engine\\training.py\", line 819, in fit\n",
      "    use_multiprocessing=use_multiprocessing)\n",
      "  File \"C:\\Users\\Hameez\\.conda\\envs\\gpu_tf\\lib\\site-packages\\tensorflow_core\\python\\keras\\engine\\training_v2.py\", line 342, in fit\n",
      "    total_epochs=epochs)\n",
      "  File \"C:\\Users\\Hameez\\.conda\\envs\\gpu_tf\\lib\\site-packages\\tensorflow_core\\python\\keras\\engine\\training_v2.py\", line 128, in run_one_epoch\n",
      "    batch_outs = execution_function(iterator)\n",
      "  File \"C:\\Users\\Hameez\\.conda\\envs\\gpu_tf\\lib\\site-packages\\tensorflow_core\\python\\keras\\engine\\training_v2_utils.py\", line 98, in execution_function\n",
      "    distributed_function(input_fn))\n",
      "  File \"C:\\Users\\Hameez\\.conda\\envs\\gpu_tf\\lib\\site-packages\\tensorflow_core\\python\\util\\nest.py\", line 568, in map_structure\n",
      "    structure[0], [func(*x) for x in entries],\n",
      "  File \"C:\\Users\\Hameez\\.conda\\envs\\gpu_tf\\lib\\site-packages\\tensorflow_core\\python\\util\\nest.py\", line 568, in <listcomp>\n",
      "    structure[0], [func(*x) for x in entries],\n",
      "  File \"C:\\Users\\Hameez\\.conda\\envs\\gpu_tf\\lib\\site-packages\\tensorflow_core\\python\\keras\\engine\\training_v2_utils.py\", line 130, in _non_none_constant_value\n",
      "    constant_value = tensor_util.constant_value(v)\n",
      "  File \"C:\\Users\\Hameez\\.conda\\envs\\gpu_tf\\lib\\site-packages\\tensorflow_core\\python\\framework\\tensor_util.py\", line 822, in constant_value\n",
      "    return tensor.numpy()\n",
      "  File \"C:\\Users\\Hameez\\.conda\\envs\\gpu_tf\\lib\\site-packages\\tensorflow_core\\python\\framework\\ops.py\", line 942, in numpy\n",
      "    maybe_arr = self._numpy()  # pylint: disable=protected-access\n",
      "  File \"C:\\Users\\Hameez\\.conda\\envs\\gpu_tf\\lib\\site-packages\\tensorflow_core\\python\\framework\\ops.py\", line 908, in _numpy\n",
      "    return self._numpy_internal()\n",
      "KeyboardInterrupt\n",
      "\n",
      "During handling of the above exception, another exception occurred:\n",
      "\n",
      "Traceback (most recent call last):\n",
      "  File \"C:\\Users\\Hameez\\.conda\\envs\\gpu_tf\\lib\\site-packages\\IPython\\core\\interactiveshell.py\", line 2045, in showtraceback\n",
      "    stb = value._render_traceback_()\n",
      "AttributeError: 'KeyboardInterrupt' object has no attribute '_render_traceback_'\n",
      "\n",
      "During handling of the above exception, another exception occurred:\n",
      "\n",
      "Traceback (most recent call last):\n",
      "  File \"C:\\Users\\Hameez\\.conda\\envs\\gpu_tf\\lib\\site-packages\\IPython\\core\\interactiveshell.py\", line 3338, in run_ast_nodes\n",
      "    if (await self.run_code(code, result,  async_=asy)):\n",
      "  File \"C:\\Users\\Hameez\\.conda\\envs\\gpu_tf\\lib\\site-packages\\IPython\\core\\interactiveshell.py\", line 3435, in run_code\n",
      "    self.showtraceback(running_compiled_code=True)\n",
      "  File \"C:\\Users\\Hameez\\.conda\\envs\\gpu_tf\\lib\\site-packages\\IPython\\core\\interactiveshell.py\", line 2048, in showtraceback\n",
      "    value, tb, tb_offset=tb_offset)\n",
      "  File \"C:\\Users\\Hameez\\.conda\\envs\\gpu_tf\\lib\\site-packages\\IPython\\core\\ultratb.py\", line 1437, in structured_traceback\n",
      "    self, etype, value, tb, tb_offset, number_of_lines_of_context)\n",
      "  File \"C:\\Users\\Hameez\\.conda\\envs\\gpu_tf\\lib\\site-packages\\IPython\\core\\ultratb.py\", line 1337, in structured_traceback\n",
      "    self, etype, value, tb, tb_offset, number_of_lines_of_context\n",
      "  File \"C:\\Users\\Hameez\\.conda\\envs\\gpu_tf\\lib\\site-packages\\IPython\\core\\ultratb.py\", line 1194, in structured_traceback\n",
      "    tb_offset)\n",
      "  File \"C:\\Users\\Hameez\\.conda\\envs\\gpu_tf\\lib\\site-packages\\IPython\\core\\ultratb.py\", line 1151, in format_exception_as_a_whole\n",
      "    last_unique, recursion_repeat = find_recursion(orig_etype, evalue, records)\n",
      "  File \"C:\\Users\\Hameez\\.conda\\envs\\gpu_tf\\lib\\site-packages\\IPython\\core\\ultratb.py\", line 451, in find_recursion\n",
      "    return len(records), 0\n",
      "TypeError: object of type 'NoneType' has no len()\n",
      "\n",
      "During handling of the above exception, another exception occurred:\n",
      "\n",
      "Traceback (most recent call last):\n",
      "  File \"C:\\Users\\Hameez\\.conda\\envs\\gpu_tf\\lib\\site-packages\\IPython\\core\\interactiveshell.py\", line 2045, in showtraceback\n",
      "    stb = value._render_traceback_()\n",
      "AttributeError: 'TypeError' object has no attribute '_render_traceback_'\n",
      "\n",
      "During handling of the above exception, another exception occurred:\n",
      "\n",
      "Traceback (most recent call last):\n",
      "  File \"C:\\Users\\Hameez\\.conda\\envs\\gpu_tf\\lib\\site-packages\\IPython\\core\\ultratb.py\", line 1170, in get_records\n",
      "    return _fixed_getinnerframes(etb, number_of_lines_of_context, tb_offset)\n",
      "  File \"C:\\Users\\Hameez\\.conda\\envs\\gpu_tf\\lib\\site-packages\\IPython\\core\\ultratb.py\", line 316, in wrapped\n",
      "    return f(*args, **kwargs)\n",
      "  File \"C:\\Users\\Hameez\\.conda\\envs\\gpu_tf\\lib\\site-packages\\IPython\\core\\ultratb.py\", line 350, in _fixed_getinnerframes\n",
      "    records = fix_frame_records_filenames(inspect.getinnerframes(etb, context))\n",
      "  File \"C:\\Users\\Hameez\\.conda\\envs\\gpu_tf\\lib\\inspect.py\", line 1502, in getinnerframes\n",
      "    frameinfo = (tb.tb_frame,) + getframeinfo(tb, context)\n",
      "  File \"C:\\Users\\Hameez\\.conda\\envs\\gpu_tf\\lib\\inspect.py\", line 1460, in getframeinfo\n",
      "    filename = getsourcefile(frame) or getfile(frame)\n",
      "  File \"C:\\Users\\Hameez\\.conda\\envs\\gpu_tf\\lib\\inspect.py\", line 696, in getsourcefile\n",
      "    if getattr(getmodule(object, filename), '__loader__', None) is not None:\n",
      "  File \"C:\\Users\\Hameez\\.conda\\envs\\gpu_tf\\lib\\inspect.py\", line 733, in getmodule\n",
      "    if ismodule(module) and hasattr(module, '__file__'):\n",
      "  File \"C:\\Users\\Hameez\\.conda\\envs\\gpu_tf\\lib\\site-packages\\tensorflow\\__init__.py\", line 50, in __getattr__\n",
      "    module = self._load()\n",
      "  File \"C:\\Users\\Hameez\\.conda\\envs\\gpu_tf\\lib\\site-packages\\tensorflow\\__init__.py\", line 44, in _load\n",
      "    module = _importlib.import_module(self.__name__)\n",
      "  File \"C:\\Users\\Hameez\\.conda\\envs\\gpu_tf\\lib\\importlib\\__init__.py\", line 127, in import_module\n",
      "    return _bootstrap._gcd_import(name[level:], package, level)\n",
      "  File \"<frozen importlib._bootstrap>\", line 1006, in _gcd_import\n",
      "  File \"<frozen importlib._bootstrap>\", line 983, in _find_and_load\n",
      "  File \"<frozen importlib._bootstrap>\", line 965, in _find_and_load_unlocked\n",
      "ModuleNotFoundError: No module named 'tensorflow_core.estimator'\n",
      "Traceback (most recent call last):\n",
      "  File \"C:\\Users\\Hameez\\.conda\\envs\\gpu_tf\\lib\\site-packages\\IPython\\core\\interactiveshell.py\", line 3418, in run_code\n",
      "    exec(code_obj, self.user_global_ns, self.user_ns)\n",
      "  File \"<ipython-input-8-89c75f9f1d70>\", line 6, in <module>\n",
      "    history = cnn_model.fit_generator(train_data, epochs=50, validation_data=test_data, verbose=1)\n",
      "  File \"C:\\Users\\Hameez\\.conda\\envs\\gpu_tf\\lib\\site-packages\\tensorflow_core\\python\\util\\deprecation.py\", line 324, in new_func\n",
      "    return func(*args, **kwargs)\n",
      "  File \"C:\\Users\\Hameez\\.conda\\envs\\gpu_tf\\lib\\site-packages\\tensorflow_core\\python\\keras\\engine\\training.py\", line 1306, in fit_generator\n",
      "    initial_epoch=initial_epoch)\n",
      "  File \"C:\\Users\\Hameez\\.conda\\envs\\gpu_tf\\lib\\site-packages\\tensorflow_core\\python\\keras\\engine\\training.py\", line 819, in fit\n",
      "    use_multiprocessing=use_multiprocessing)\n",
      "  File \"C:\\Users\\Hameez\\.conda\\envs\\gpu_tf\\lib\\site-packages\\tensorflow_core\\python\\keras\\engine\\training_v2.py\", line 342, in fit\n",
      "    total_epochs=epochs)\n",
      "  File \"C:\\Users\\Hameez\\.conda\\envs\\gpu_tf\\lib\\site-packages\\tensorflow_core\\python\\keras\\engine\\training_v2.py\", line 128, in run_one_epoch\n",
      "    batch_outs = execution_function(iterator)\n",
      "  File \"C:\\Users\\Hameez\\.conda\\envs\\gpu_tf\\lib\\site-packages\\tensorflow_core\\python\\keras\\engine\\training_v2_utils.py\", line 98, in execution_function\n",
      "    distributed_function(input_fn))\n",
      "  File \"C:\\Users\\Hameez\\.conda\\envs\\gpu_tf\\lib\\site-packages\\tensorflow_core\\python\\util\\nest.py\", line 568, in map_structure\n",
      "    structure[0], [func(*x) for x in entries],\n",
      "  File \"C:\\Users\\Hameez\\.conda\\envs\\gpu_tf\\lib\\site-packages\\tensorflow_core\\python\\util\\nest.py\", line 568, in <listcomp>\n",
      "    structure[0], [func(*x) for x in entries],\n",
      "  File \"C:\\Users\\Hameez\\.conda\\envs\\gpu_tf\\lib\\site-packages\\tensorflow_core\\python\\keras\\engine\\training_v2_utils.py\", line 130, in _non_none_constant_value\n",
      "    constant_value = tensor_util.constant_value(v)\n",
      "  File \"C:\\Users\\Hameez\\.conda\\envs\\gpu_tf\\lib\\site-packages\\tensorflow_core\\python\\framework\\tensor_util.py\", line 822, in constant_value\n",
      "    return tensor.numpy()\n",
      "  File \"C:\\Users\\Hameez\\.conda\\envs\\gpu_tf\\lib\\site-packages\\tensorflow_core\\python\\framework\\ops.py\", line 942, in numpy\n",
      "    maybe_arr = self._numpy()  # pylint: disable=protected-access\n",
      "  File \"C:\\Users\\Hameez\\.conda\\envs\\gpu_tf\\lib\\site-packages\\tensorflow_core\\python\\framework\\ops.py\", line 908, in _numpy\n",
      "    return self._numpy_internal()\n",
      "KeyboardInterrupt\n",
      "\n",
      "During handling of the above exception, another exception occurred:\n",
      "\n",
      "Traceback (most recent call last):\n",
      "  File \"C:\\Users\\Hameez\\.conda\\envs\\gpu_tf\\lib\\site-packages\\IPython\\core\\interactiveshell.py\", line 2045, in showtraceback\n",
      "    stb = value._render_traceback_()\n",
      "AttributeError: 'KeyboardInterrupt' object has no attribute '_render_traceback_'\n",
      "\n",
      "During handling of the above exception, another exception occurred:\n",
      "\n",
      "Traceback (most recent call last):\n",
      "  File \"C:\\Users\\Hameez\\.conda\\envs\\gpu_tf\\lib\\site-packages\\IPython\\core\\interactiveshell.py\", line 3338, in run_ast_nodes\n",
      "    if (await self.run_code(code, result,  async_=asy)):\n",
      "  File \"C:\\Users\\Hameez\\.conda\\envs\\gpu_tf\\lib\\site-packages\\IPython\\core\\interactiveshell.py\", line 3435, in run_code\n",
      "    self.showtraceback(running_compiled_code=True)\n",
      "  File \"C:\\Users\\Hameez\\.conda\\envs\\gpu_tf\\lib\\site-packages\\IPython\\core\\interactiveshell.py\", line 2048, in showtraceback\n",
      "    value, tb, tb_offset=tb_offset)\n",
      "  File \"C:\\Users\\Hameez\\.conda\\envs\\gpu_tf\\lib\\site-packages\\IPython\\core\\ultratb.py\", line 1437, in structured_traceback\n",
      "    self, etype, value, tb, tb_offset, number_of_lines_of_context)\n",
      "  File \"C:\\Users\\Hameez\\.conda\\envs\\gpu_tf\\lib\\site-packages\\IPython\\core\\ultratb.py\", line 1337, in structured_traceback\n",
      "    self, etype, value, tb, tb_offset, number_of_lines_of_context\n",
      "  File \"C:\\Users\\Hameez\\.conda\\envs\\gpu_tf\\lib\\site-packages\\IPython\\core\\ultratb.py\", line 1194, in structured_traceback\n",
      "    tb_offset)\n",
      "  File \"C:\\Users\\Hameez\\.conda\\envs\\gpu_tf\\lib\\site-packages\\IPython\\core\\ultratb.py\", line 1151, in format_exception_as_a_whole\n",
      "    last_unique, recursion_repeat = find_recursion(orig_etype, evalue, records)\n",
      "  File \"C:\\Users\\Hameez\\.conda\\envs\\gpu_tf\\lib\\site-packages\\IPython\\core\\ultratb.py\", line 451, in find_recursion\n",
      "    return len(records), 0\n",
      "TypeError: object of type 'NoneType' has no len()\n",
      "\n",
      "During handling of the above exception, another exception occurred:\n",
      "\n",
      "Traceback (most recent call last):\n",
      "  File \"C:\\Users\\Hameez\\.conda\\envs\\gpu_tf\\lib\\site-packages\\IPython\\core\\interactiveshell.py\", line 2045, in showtraceback\n",
      "    stb = value._render_traceback_()\n",
      "AttributeError: 'TypeError' object has no attribute '_render_traceback_'\n",
      "\n",
      "During handling of the above exception, another exception occurred:\n",
      "\n",
      "Traceback (most recent call last):\n",
      "  File \"C:\\Users\\Hameez\\.conda\\envs\\gpu_tf\\lib\\site-packages\\IPython\\core\\interactiveshell.py\", line 2923, in _run_cell\n",
      "    return runner(coro)\n",
      "  File \"C:\\Users\\Hameez\\.conda\\envs\\gpu_tf\\lib\\site-packages\\IPython\\core\\async_helpers.py\", line 68, in _pseudo_sync_runner\n",
      "    coro.send(None)\n",
      "  File \"C:\\Users\\Hameez\\.conda\\envs\\gpu_tf\\lib\\site-packages\\IPython\\core\\interactiveshell.py\", line 3147, in run_cell_async\n",
      "    interactivity=interactivity, compiler=compiler, result=result)\n",
      "  File \"C:\\Users\\Hameez\\.conda\\envs\\gpu_tf\\lib\\site-packages\\IPython\\core\\interactiveshell.py\", line 3357, in run_ast_nodes\n",
      "    self.showtraceback()\n",
      "  File \"C:\\Users\\Hameez\\.conda\\envs\\gpu_tf\\lib\\site-packages\\IPython\\core\\interactiveshell.py\", line 2048, in showtraceback\n",
      "    value, tb, tb_offset=tb_offset)\n",
      "  File \"C:\\Users\\Hameez\\.conda\\envs\\gpu_tf\\lib\\site-packages\\IPython\\core\\ultratb.py\", line 1437, in structured_traceback\n",
      "    self, etype, value, tb, tb_offset, number_of_lines_of_context)\n",
      "  File \"C:\\Users\\Hameez\\.conda\\envs\\gpu_tf\\lib\\site-packages\\IPython\\core\\ultratb.py\", line 1337, in structured_traceback\n",
      "    self, etype, value, tb, tb_offset, number_of_lines_of_context\n",
      "  File \"C:\\Users\\Hameez\\.conda\\envs\\gpu_tf\\lib\\site-packages\\IPython\\core\\ultratb.py\", line 1212, in structured_traceback\n",
      "    chained_exceptions_tb_offset)\n",
      "  File \"C:\\Users\\Hameez\\.conda\\envs\\gpu_tf\\lib\\site-packages\\IPython\\core\\ultratb.py\", line 1151, in format_exception_as_a_whole\n",
      "    last_unique, recursion_repeat = find_recursion(orig_etype, evalue, records)\n",
      "  File \"C:\\Users\\Hameez\\.conda\\envs\\gpu_tf\\lib\\site-packages\\IPython\\core\\ultratb.py\", line 451, in find_recursion\n",
      "    return len(records), 0\n",
      "TypeError: object of type 'NoneType' has no len()\n",
      "\n",
      "During handling of the above exception, another exception occurred:\n",
      "\n",
      "Traceback (most recent call last):\n",
      "  File \"C:\\Users\\Hameez\\.conda\\envs\\gpu_tf\\lib\\site-packages\\IPython\\core\\interactiveshell.py\", line 2045, in showtraceback\n",
      "    stb = value._render_traceback_()\n",
      "AttributeError: 'TypeError' object has no attribute '_render_traceback_'\n",
      "\n",
      "During handling of the above exception, another exception occurred:\n",
      "\n",
      "Traceback (most recent call last):\n",
      "  File \"C:\\Users\\Hameez\\.conda\\envs\\gpu_tf\\lib\\site-packages\\IPython\\core\\ultratb.py\", line 1170, in get_records\n",
      "    return _fixed_getinnerframes(etb, number_of_lines_of_context, tb_offset)\n",
      "  File \"C:\\Users\\Hameez\\.conda\\envs\\gpu_tf\\lib\\site-packages\\IPython\\core\\ultratb.py\", line 316, in wrapped\n",
      "    return f(*args, **kwargs)\n",
      "  File \"C:\\Users\\Hameez\\.conda\\envs\\gpu_tf\\lib\\site-packages\\IPython\\core\\ultratb.py\", line 350, in _fixed_getinnerframes\n",
      "    records = fix_frame_records_filenames(inspect.getinnerframes(etb, context))\n",
      "  File \"C:\\Users\\Hameez\\.conda\\envs\\gpu_tf\\lib\\inspect.py\", line 1502, in getinnerframes\n",
      "    frameinfo = (tb.tb_frame,) + getframeinfo(tb, context)\n",
      "  File \"C:\\Users\\Hameez\\.conda\\envs\\gpu_tf\\lib\\inspect.py\", line 1460, in getframeinfo\n",
      "    filename = getsourcefile(frame) or getfile(frame)\n",
      "  File \"C:\\Users\\Hameez\\.conda\\envs\\gpu_tf\\lib\\inspect.py\", line 696, in getsourcefile\n",
      "    if getattr(getmodule(object, filename), '__loader__', None) is not None:\n",
      "  File \"C:\\Users\\Hameez\\.conda\\envs\\gpu_tf\\lib\\inspect.py\", line 733, in getmodule\n",
      "    if ismodule(module) and hasattr(module, '__file__'):\n",
      "  File \"C:\\Users\\Hameez\\.conda\\envs\\gpu_tf\\lib\\site-packages\\tensorflow\\__init__.py\", line 50, in __getattr__\n",
      "    module = self._load()\n",
      "  File \"C:\\Users\\Hameez\\.conda\\envs\\gpu_tf\\lib\\site-packages\\tensorflow\\__init__.py\", line 44, in _load\n",
      "    module = _importlib.import_module(self.__name__)\n",
      "  File \"C:\\Users\\Hameez\\.conda\\envs\\gpu_tf\\lib\\importlib\\__init__.py\", line 127, in import_module\n",
      "    return _bootstrap._gcd_import(name[level:], package, level)\n",
      "  File \"<frozen importlib._bootstrap>\", line 1006, in _gcd_import\n",
      "  File \"<frozen importlib._bootstrap>\", line 983, in _find_and_load\n",
      "  File \"<frozen importlib._bootstrap>\", line 965, in _find_and_load_unlocked\n",
      "ModuleNotFoundError: No module named 'tensorflow_core.estimator'\n"
     ]
    }
   ],
   "source": [
    "sgd = SGD(lr=1e-3, decay=1e-6, momentum=0.9, nesterov=True)\n",
    "cnn_model.compile(loss='categorical_crossentropy',\n",
    "                  optimizer=sgd,\n",
    "                  metrics=['accuracy'])\n",
    "\n",
    "history = cnn_model.fit_generator(train_data, epochs=50, validation_data=test_data, verbose=1)"
   ]
  },
  {
   "cell_type": "code",
   "execution_count": null,
   "metadata": {},
   "outputs": [
    {
     "name": "stderr",
     "output_type": "stream",
     "text": [
      "ERROR:root:Internal Python error in the inspect module.\n",
      "Below is the traceback from this internal error.\n",
      "\n",
      "ERROR:root:Internal Python error in the inspect module.\n",
      "Below is the traceback from this internal error.\n",
      "\n",
      "ERROR:root:Internal Python error in the inspect module.\n",
      "Below is the traceback from this internal error.\n",
      "\n"
     ]
    },
    {
     "name": "stdout",
     "output_type": "stream",
     "text": [
      "Traceback (most recent call last):\n",
      "  File \"C:\\Users\\Hameez\\.conda\\envs\\gpu_tf\\lib\\site-packages\\IPython\\core\\interactiveshell.py\", line 3418, in run_code\n",
      "    exec(code_obj, self.user_global_ns, self.user_ns)\n",
      "  File \"<ipython-input-8-377a4e210667>\", line 2, in <module>\n",
      "    plt.plot(history.history['accuracy'])\n",
      "NameError: name 'history' is not defined\n",
      "\n",
      "During handling of the above exception, another exception occurred:\n",
      "\n",
      "Traceback (most recent call last):\n",
      "  File \"C:\\Users\\Hameez\\.conda\\envs\\gpu_tf\\lib\\site-packages\\IPython\\core\\interactiveshell.py\", line 2045, in showtraceback\n",
      "    stb = value._render_traceback_()\n",
      "AttributeError: 'NameError' object has no attribute '_render_traceback_'\n",
      "\n",
      "During handling of the above exception, another exception occurred:\n",
      "\n",
      "Traceback (most recent call last):\n",
      "  File \"C:\\Users\\Hameez\\.conda\\envs\\gpu_tf\\lib\\site-packages\\IPython\\core\\ultratb.py\", line 1170, in get_records\n",
      "    return _fixed_getinnerframes(etb, number_of_lines_of_context, tb_offset)\n",
      "  File \"C:\\Users\\Hameez\\.conda\\envs\\gpu_tf\\lib\\site-packages\\IPython\\core\\ultratb.py\", line 316, in wrapped\n",
      "    return f(*args, **kwargs)\n",
      "  File \"C:\\Users\\Hameez\\.conda\\envs\\gpu_tf\\lib\\site-packages\\IPython\\core\\ultratb.py\", line 350, in _fixed_getinnerframes\n",
      "    records = fix_frame_records_filenames(inspect.getinnerframes(etb, context))\n",
      "  File \"C:\\Users\\Hameez\\.conda\\envs\\gpu_tf\\lib\\inspect.py\", line 1502, in getinnerframes\n",
      "    frameinfo = (tb.tb_frame,) + getframeinfo(tb, context)\n",
      "  File \"C:\\Users\\Hameez\\.conda\\envs\\gpu_tf\\lib\\inspect.py\", line 1460, in getframeinfo\n",
      "    filename = getsourcefile(frame) or getfile(frame)\n",
      "  File \"C:\\Users\\Hameez\\.conda\\envs\\gpu_tf\\lib\\inspect.py\", line 696, in getsourcefile\n",
      "    if getattr(getmodule(object, filename), '__loader__', None) is not None:\n",
      "  File \"C:\\Users\\Hameez\\.conda\\envs\\gpu_tf\\lib\\inspect.py\", line 733, in getmodule\n",
      "    if ismodule(module) and hasattr(module, '__file__'):\n",
      "  File \"C:\\Users\\Hameez\\.conda\\envs\\gpu_tf\\lib\\site-packages\\tensorflow\\__init__.py\", line 50, in __getattr__\n",
      "    module = self._load()\n",
      "  File \"C:\\Users\\Hameez\\.conda\\envs\\gpu_tf\\lib\\site-packages\\tensorflow\\__init__.py\", line 44, in _load\n",
      "    module = _importlib.import_module(self.__name__)\n",
      "  File \"C:\\Users\\Hameez\\.conda\\envs\\gpu_tf\\lib\\importlib\\__init__.py\", line 127, in import_module\n",
      "    return _bootstrap._gcd_import(name[level:], package, level)\n",
      "  File \"<frozen importlib._bootstrap>\", line 1006, in _gcd_import\n",
      "  File \"<frozen importlib._bootstrap>\", line 983, in _find_and_load\n",
      "  File \"<frozen importlib._bootstrap>\", line 965, in _find_and_load_unlocked\n",
      "ModuleNotFoundError: No module named 'tensorflow_core.estimator'\n",
      "Traceback (most recent call last):\n",
      "  File \"C:\\Users\\Hameez\\.conda\\envs\\gpu_tf\\lib\\site-packages\\IPython\\core\\interactiveshell.py\", line 3418, in run_code\n",
      "    exec(code_obj, self.user_global_ns, self.user_ns)\n",
      "  File \"<ipython-input-8-377a4e210667>\", line 2, in <module>\n",
      "    plt.plot(history.history['accuracy'])\n",
      "NameError: name 'history' is not defined\n",
      "\n",
      "During handling of the above exception, another exception occurred:\n",
      "\n",
      "Traceback (most recent call last):\n",
      "  File \"C:\\Users\\Hameez\\.conda\\envs\\gpu_tf\\lib\\site-packages\\IPython\\core\\interactiveshell.py\", line 2045, in showtraceback\n",
      "    stb = value._render_traceback_()\n",
      "AttributeError: 'NameError' object has no attribute '_render_traceback_'\n",
      "\n",
      "During handling of the above exception, another exception occurred:\n",
      "\n",
      "Traceback (most recent call last):\n",
      "  File \"C:\\Users\\Hameez\\.conda\\envs\\gpu_tf\\lib\\site-packages\\IPython\\core\\interactiveshell.py\", line 3338, in run_ast_nodes\n",
      "    if (await self.run_code(code, result,  async_=asy)):\n",
      "  File \"C:\\Users\\Hameez\\.conda\\envs\\gpu_tf\\lib\\site-packages\\IPython\\core\\interactiveshell.py\", line 3435, in run_code\n",
      "    self.showtraceback(running_compiled_code=True)\n",
      "  File \"C:\\Users\\Hameez\\.conda\\envs\\gpu_tf\\lib\\site-packages\\IPython\\core\\interactiveshell.py\", line 2048, in showtraceback\n",
      "    value, tb, tb_offset=tb_offset)\n",
      "  File \"C:\\Users\\Hameez\\.conda\\envs\\gpu_tf\\lib\\site-packages\\IPython\\core\\ultratb.py\", line 1437, in structured_traceback\n",
      "    self, etype, value, tb, tb_offset, number_of_lines_of_context)\n",
      "  File \"C:\\Users\\Hameez\\.conda\\envs\\gpu_tf\\lib\\site-packages\\IPython\\core\\ultratb.py\", line 1337, in structured_traceback\n",
      "    self, etype, value, tb, tb_offset, number_of_lines_of_context\n",
      "  File \"C:\\Users\\Hameez\\.conda\\envs\\gpu_tf\\lib\\site-packages\\IPython\\core\\ultratb.py\", line 1194, in structured_traceback\n",
      "    tb_offset)\n",
      "  File \"C:\\Users\\Hameez\\.conda\\envs\\gpu_tf\\lib\\site-packages\\IPython\\core\\ultratb.py\", line 1151, in format_exception_as_a_whole\n",
      "    last_unique, recursion_repeat = find_recursion(orig_etype, evalue, records)\n",
      "  File \"C:\\Users\\Hameez\\.conda\\envs\\gpu_tf\\lib\\site-packages\\IPython\\core\\ultratb.py\", line 451, in find_recursion\n",
      "    return len(records), 0\n",
      "TypeError: object of type 'NoneType' has no len()\n",
      "\n",
      "During handling of the above exception, another exception occurred:\n",
      "\n",
      "Traceback (most recent call last):\n",
      "  File \"C:\\Users\\Hameez\\.conda\\envs\\gpu_tf\\lib\\site-packages\\IPython\\core\\interactiveshell.py\", line 2045, in showtraceback\n",
      "    stb = value._render_traceback_()\n",
      "AttributeError: 'TypeError' object has no attribute '_render_traceback_'\n",
      "\n",
      "During handling of the above exception, another exception occurred:\n",
      "\n",
      "Traceback (most recent call last):\n",
      "  File \"C:\\Users\\Hameez\\.conda\\envs\\gpu_tf\\lib\\site-packages\\IPython\\core\\ultratb.py\", line 1170, in get_records\n",
      "    return _fixed_getinnerframes(etb, number_of_lines_of_context, tb_offset)\n",
      "  File \"C:\\Users\\Hameez\\.conda\\envs\\gpu_tf\\lib\\site-packages\\IPython\\core\\ultratb.py\", line 316, in wrapped\n",
      "    return f(*args, **kwargs)\n",
      "  File \"C:\\Users\\Hameez\\.conda\\envs\\gpu_tf\\lib\\site-packages\\IPython\\core\\ultratb.py\", line 350, in _fixed_getinnerframes\n",
      "    records = fix_frame_records_filenames(inspect.getinnerframes(etb, context))\n",
      "  File \"C:\\Users\\Hameez\\.conda\\envs\\gpu_tf\\lib\\inspect.py\", line 1502, in getinnerframes\n",
      "    frameinfo = (tb.tb_frame,) + getframeinfo(tb, context)\n",
      "  File \"C:\\Users\\Hameez\\.conda\\envs\\gpu_tf\\lib\\inspect.py\", line 1460, in getframeinfo\n",
      "    filename = getsourcefile(frame) or getfile(frame)\n",
      "  File \"C:\\Users\\Hameez\\.conda\\envs\\gpu_tf\\lib\\inspect.py\", line 696, in getsourcefile\n",
      "    if getattr(getmodule(object, filename), '__loader__', None) is not None:\n",
      "  File \"C:\\Users\\Hameez\\.conda\\envs\\gpu_tf\\lib\\inspect.py\", line 733, in getmodule\n",
      "    if ismodule(module) and hasattr(module, '__file__'):\n",
      "  File \"C:\\Users\\Hameez\\.conda\\envs\\gpu_tf\\lib\\site-packages\\tensorflow\\__init__.py\", line 50, in __getattr__\n",
      "    module = self._load()\n",
      "  File \"C:\\Users\\Hameez\\.conda\\envs\\gpu_tf\\lib\\site-packages\\tensorflow\\__init__.py\", line 44, in _load\n",
      "    module = _importlib.import_module(self.__name__)\n",
      "  File \"C:\\Users\\Hameez\\.conda\\envs\\gpu_tf\\lib\\importlib\\__init__.py\", line 127, in import_module\n",
      "    return _bootstrap._gcd_import(name[level:], package, level)\n",
      "  File \"<frozen importlib._bootstrap>\", line 1006, in _gcd_import\n",
      "  File \"<frozen importlib._bootstrap>\", line 983, in _find_and_load\n",
      "  File \"<frozen importlib._bootstrap>\", line 965, in _find_and_load_unlocked\n",
      "ModuleNotFoundError: No module named 'tensorflow_core.estimator'\n",
      "Traceback (most recent call last):\n",
      "  File \"C:\\Users\\Hameez\\.conda\\envs\\gpu_tf\\lib\\site-packages\\IPython\\core\\interactiveshell.py\", line 3418, in run_code\n",
      "    exec(code_obj, self.user_global_ns, self.user_ns)\n",
      "  File \"<ipython-input-8-377a4e210667>\", line 2, in <module>\n",
      "    plt.plot(history.history['accuracy'])\n",
      "NameError: name 'history' is not defined\n",
      "\n",
      "During handling of the above exception, another exception occurred:\n",
      "\n",
      "Traceback (most recent call last):\n",
      "  File \"C:\\Users\\Hameez\\.conda\\envs\\gpu_tf\\lib\\site-packages\\IPython\\core\\interactiveshell.py\", line 2045, in showtraceback\n",
      "    stb = value._render_traceback_()\n",
      "AttributeError: 'NameError' object has no attribute '_render_traceback_'\n",
      "\n",
      "During handling of the above exception, another exception occurred:\n",
      "\n",
      "Traceback (most recent call last):\n",
      "  File \"C:\\Users\\Hameez\\.conda\\envs\\gpu_tf\\lib\\site-packages\\IPython\\core\\interactiveshell.py\", line 3338, in run_ast_nodes\n",
      "    if (await self.run_code(code, result,  async_=asy)):\n",
      "  File \"C:\\Users\\Hameez\\.conda\\envs\\gpu_tf\\lib\\site-packages\\IPython\\core\\interactiveshell.py\", line 3435, in run_code\n",
      "    self.showtraceback(running_compiled_code=True)\n",
      "  File \"C:\\Users\\Hameez\\.conda\\envs\\gpu_tf\\lib\\site-packages\\IPython\\core\\interactiveshell.py\", line 2048, in showtraceback\n",
      "    value, tb, tb_offset=tb_offset)\n",
      "  File \"C:\\Users\\Hameez\\.conda\\envs\\gpu_tf\\lib\\site-packages\\IPython\\core\\ultratb.py\", line 1437, in structured_traceback\n",
      "    self, etype, value, tb, tb_offset, number_of_lines_of_context)\n",
      "  File \"C:\\Users\\Hameez\\.conda\\envs\\gpu_tf\\lib\\site-packages\\IPython\\core\\ultratb.py\", line 1337, in structured_traceback\n",
      "    self, etype, value, tb, tb_offset, number_of_lines_of_context\n",
      "  File \"C:\\Users\\Hameez\\.conda\\envs\\gpu_tf\\lib\\site-packages\\IPython\\core\\ultratb.py\", line 1194, in structured_traceback\n",
      "    tb_offset)\n",
      "  File \"C:\\Users\\Hameez\\.conda\\envs\\gpu_tf\\lib\\site-packages\\IPython\\core\\ultratb.py\", line 1151, in format_exception_as_a_whole\n",
      "    last_unique, recursion_repeat = find_recursion(orig_etype, evalue, records)\n",
      "  File \"C:\\Users\\Hameez\\.conda\\envs\\gpu_tf\\lib\\site-packages\\IPython\\core\\ultratb.py\", line 451, in find_recursion\n",
      "    return len(records), 0\n",
      "TypeError: object of type 'NoneType' has no len()\n",
      "\n",
      "During handling of the above exception, another exception occurred:\n",
      "\n",
      "Traceback (most recent call last):\n",
      "  File \"C:\\Users\\Hameez\\.conda\\envs\\gpu_tf\\lib\\site-packages\\IPython\\core\\interactiveshell.py\", line 2045, in showtraceback\n",
      "    stb = value._render_traceback_()\n",
      "AttributeError: 'TypeError' object has no attribute '_render_traceback_'\n",
      "\n",
      "During handling of the above exception, another exception occurred:\n",
      "\n",
      "Traceback (most recent call last):\n",
      "  File \"C:\\Users\\Hameez\\.conda\\envs\\gpu_tf\\lib\\site-packages\\IPython\\core\\interactiveshell.py\", line 2923, in _run_cell\n",
      "    return runner(coro)\n",
      "  File \"C:\\Users\\Hameez\\.conda\\envs\\gpu_tf\\lib\\site-packages\\IPython\\core\\async_helpers.py\", line 68, in _pseudo_sync_runner\n",
      "    coro.send(None)\n",
      "  File \"C:\\Users\\Hameez\\.conda\\envs\\gpu_tf\\lib\\site-packages\\IPython\\core\\interactiveshell.py\", line 3147, in run_cell_async\n",
      "    interactivity=interactivity, compiler=compiler, result=result)\n",
      "  File \"C:\\Users\\Hameez\\.conda\\envs\\gpu_tf\\lib\\site-packages\\IPython\\core\\interactiveshell.py\", line 3357, in run_ast_nodes\n",
      "    self.showtraceback()\n",
      "  File \"C:\\Users\\Hameez\\.conda\\envs\\gpu_tf\\lib\\site-packages\\IPython\\core\\interactiveshell.py\", line 2048, in showtraceback\n",
      "    value, tb, tb_offset=tb_offset)\n",
      "  File \"C:\\Users\\Hameez\\.conda\\envs\\gpu_tf\\lib\\site-packages\\IPython\\core\\ultratb.py\", line 1437, in structured_traceback\n",
      "    self, etype, value, tb, tb_offset, number_of_lines_of_context)\n",
      "  File \"C:\\Users\\Hameez\\.conda\\envs\\gpu_tf\\lib\\site-packages\\IPython\\core\\ultratb.py\", line 1337, in structured_traceback\n",
      "    self, etype, value, tb, tb_offset, number_of_lines_of_context\n",
      "  File \"C:\\Users\\Hameez\\.conda\\envs\\gpu_tf\\lib\\site-packages\\IPython\\core\\ultratb.py\", line 1212, in structured_traceback\n",
      "    chained_exceptions_tb_offset)\n",
      "  File \"C:\\Users\\Hameez\\.conda\\envs\\gpu_tf\\lib\\site-packages\\IPython\\core\\ultratb.py\", line 1151, in format_exception_as_a_whole\n",
      "    last_unique, recursion_repeat = find_recursion(orig_etype, evalue, records)\n",
      "  File \"C:\\Users\\Hameez\\.conda\\envs\\gpu_tf\\lib\\site-packages\\IPython\\core\\ultratb.py\", line 451, in find_recursion\n",
      "    return len(records), 0\n",
      "TypeError: object of type 'NoneType' has no len()\n",
      "\n",
      "During handling of the above exception, another exception occurred:\n",
      "\n",
      "Traceback (most recent call last):\n",
      "  File \"C:\\Users\\Hameez\\.conda\\envs\\gpu_tf\\lib\\site-packages\\IPython\\core\\interactiveshell.py\", line 2045, in showtraceback\n",
      "    stb = value._render_traceback_()\n",
      "AttributeError: 'TypeError' object has no attribute '_render_traceback_'\n",
      "\n",
      "During handling of the above exception, another exception occurred:\n",
      "\n",
      "Traceback (most recent call last):\n",
      "  File \"C:\\Users\\Hameez\\.conda\\envs\\gpu_tf\\lib\\site-packages\\IPython\\core\\ultratb.py\", line 1170, in get_records\n",
      "    return _fixed_getinnerframes(etb, number_of_lines_of_context, tb_offset)\n",
      "  File \"C:\\Users\\Hameez\\.conda\\envs\\gpu_tf\\lib\\site-packages\\IPython\\core\\ultratb.py\", line 316, in wrapped\n",
      "    return f(*args, **kwargs)\n",
      "  File \"C:\\Users\\Hameez\\.conda\\envs\\gpu_tf\\lib\\site-packages\\IPython\\core\\ultratb.py\", line 350, in _fixed_getinnerframes\n",
      "    records = fix_frame_records_filenames(inspect.getinnerframes(etb, context))\n",
      "  File \"C:\\Users\\Hameez\\.conda\\envs\\gpu_tf\\lib\\inspect.py\", line 1502, in getinnerframes\n",
      "    frameinfo = (tb.tb_frame,) + getframeinfo(tb, context)\n",
      "  File \"C:\\Users\\Hameez\\.conda\\envs\\gpu_tf\\lib\\inspect.py\", line 1460, in getframeinfo\n",
      "    filename = getsourcefile(frame) or getfile(frame)\n",
      "  File \"C:\\Users\\Hameez\\.conda\\envs\\gpu_tf\\lib\\inspect.py\", line 696, in getsourcefile\n",
      "    if getattr(getmodule(object, filename), '__loader__', None) is not None:\n",
      "  File \"C:\\Users\\Hameez\\.conda\\envs\\gpu_tf\\lib\\inspect.py\", line 733, in getmodule\n",
      "    if ismodule(module) and hasattr(module, '__file__'):\n",
      "  File \"C:\\Users\\Hameez\\.conda\\envs\\gpu_tf\\lib\\site-packages\\tensorflow\\__init__.py\", line 50, in __getattr__\n",
      "    module = self._load()\n",
      "  File \"C:\\Users\\Hameez\\.conda\\envs\\gpu_tf\\lib\\site-packages\\tensorflow\\__init__.py\", line 44, in _load\n",
      "    module = _importlib.import_module(self.__name__)\n",
      "  File \"C:\\Users\\Hameez\\.conda\\envs\\gpu_tf\\lib\\importlib\\__init__.py\", line 127, in import_module\n",
      "    return _bootstrap._gcd_import(name[level:], package, level)\n",
      "  File \"<frozen importlib._bootstrap>\", line 1006, in _gcd_import\n",
      "  File \"<frozen importlib._bootstrap>\", line 983, in _find_and_load\n",
      "  File \"<frozen importlib._bootstrap>\", line 965, in _find_and_load_unlocked\n",
      "ModuleNotFoundError: No module named 'tensorflow_core.estimator'\n"
     ]
    }
   ],
   "source": [
    "# summarize history for accuracy\n",
    "plt.plot(history.history['accuracy'])\n",
    "plt.plot(history.history['val_accuracy'])\n",
    "plt.title('model accuracy')\n",
    "plt.ylabel('accuracy')\n",
    "plt.xlabel('epoch')\n",
    "plt.legend(['train', 'test'], loc='upper left')\n",
    "plt.show()"
   ]
  },
  {
   "cell_type": "code",
   "execution_count": null,
   "metadata": {},
   "outputs": [
    {
     "name": "stdout",
     "output_type": "stream",
     "text": [
      "ERROR! Session/line number was not unique in database. History logging moved to new session 1023\n"
     ]
    },
    {
     "name": "stderr",
     "output_type": "stream",
     "text": [
      "ERROR:root:Internal Python error in the inspect module.\n",
      "Below is the traceback from this internal error.\n",
      "\n",
      "ERROR:root:Internal Python error in the inspect module.\n",
      "Below is the traceback from this internal error.\n",
      "\n"
     ]
    },
    {
     "name": "stdout",
     "output_type": "stream",
     "text": [
      "Traceback (most recent call last):\n",
      "  File \"C:\\Users\\Hameez\\.conda\\envs\\gpu_tf\\lib\\site-packages\\IPython\\core\\interactiveshell.py\", line 3418, in run_code\n",
      "    exec(code_obj, self.user_global_ns, self.user_ns)\n",
      "  File \"<ipython-input-8-d737d78baf69>\", line 2, in <module>\n",
      "    plt.plot(history.history['loss'])\n",
      "NameError: name 'history' is not defined\n",
      "\n",
      "During handling of the above exception, another exception occurred:\n",
      "\n",
      "Traceback (most recent call last):\n",
      "  File \"C:\\Users\\Hameez\\.conda\\envs\\gpu_tf\\lib\\site-packages\\IPython\\core\\interactiveshell.py\", line 2045, in showtraceback\n",
      "    stb = value._render_traceback_()\n",
      "AttributeError: 'NameError' object has no attribute '_render_traceback_'\n",
      "\n",
      "During handling of the above exception, another exception occurred:\n",
      "\n",
      "Traceback (most recent call last):\n",
      "  File \"C:\\Users\\Hameez\\.conda\\envs\\gpu_tf\\lib\\site-packages\\IPython\\core\\ultratb.py\", line 1170, in get_records\n",
      "    return _fixed_getinnerframes(etb, number_of_lines_of_context, tb_offset)\n",
      "  File \"C:\\Users\\Hameez\\.conda\\envs\\gpu_tf\\lib\\site-packages\\IPython\\core\\ultratb.py\", line 316, in wrapped\n",
      "    return f(*args, **kwargs)\n",
      "  File \"C:\\Users\\Hameez\\.conda\\envs\\gpu_tf\\lib\\site-packages\\IPython\\core\\ultratb.py\", line 350, in _fixed_getinnerframes\n",
      "    records = fix_frame_records_filenames(inspect.getinnerframes(etb, context))\n",
      "  File \"C:\\Users\\Hameez\\.conda\\envs\\gpu_tf\\lib\\inspect.py\", line 1502, in getinnerframes\n",
      "    frameinfo = (tb.tb_frame,) + getframeinfo(tb, context)\n",
      "  File \"C:\\Users\\Hameez\\.conda\\envs\\gpu_tf\\lib\\inspect.py\", line 1460, in getframeinfo\n",
      "    filename = getsourcefile(frame) or getfile(frame)\n",
      "  File \"C:\\Users\\Hameez\\.conda\\envs\\gpu_tf\\lib\\inspect.py\", line 696, in getsourcefile\n",
      "    if getattr(getmodule(object, filename), '__loader__', None) is not None:\n",
      "  File \"C:\\Users\\Hameez\\.conda\\envs\\gpu_tf\\lib\\inspect.py\", line 733, in getmodule\n",
      "    if ismodule(module) and hasattr(module, '__file__'):\n",
      "  File \"C:\\Users\\Hameez\\.conda\\envs\\gpu_tf\\lib\\site-packages\\tensorflow\\__init__.py\", line 50, in __getattr__\n",
      "    module = self._load()\n",
      "  File \"C:\\Users\\Hameez\\.conda\\envs\\gpu_tf\\lib\\site-packages\\tensorflow\\__init__.py\", line 44, in _load\n",
      "    module = _importlib.import_module(self.__name__)\n",
      "  File \"C:\\Users\\Hameez\\.conda\\envs\\gpu_tf\\lib\\importlib\\__init__.py\", line 127, in import_module\n",
      "    return _bootstrap._gcd_import(name[level:], package, level)\n",
      "  File \"<frozen importlib._bootstrap>\", line 1006, in _gcd_import\n",
      "  File \"<frozen importlib._bootstrap>\", line 983, in _find_and_load\n",
      "  File \"<frozen importlib._bootstrap>\", line 965, in _find_and_load_unlocked\n",
      "ModuleNotFoundError: No module named 'tensorflow_core.estimator'\n"
     ]
    },
    {
     "name": "stderr",
     "output_type": "stream",
     "text": [
      "ERROR:root:Internal Python error in the inspect module.\n",
      "Below is the traceback from this internal error.\n",
      "\n"
     ]
    },
    {
     "name": "stdout",
     "output_type": "stream",
     "text": [
      "Traceback (most recent call last):\n",
      "  File \"C:\\Users\\Hameez\\.conda\\envs\\gpu_tf\\lib\\site-packages\\IPython\\core\\interactiveshell.py\", line 3418, in run_code\n",
      "    exec(code_obj, self.user_global_ns, self.user_ns)\n",
      "  File \"<ipython-input-8-d737d78baf69>\", line 2, in <module>\n",
      "    plt.plot(history.history['loss'])\n",
      "NameError: name 'history' is not defined\n",
      "\n",
      "During handling of the above exception, another exception occurred:\n",
      "\n",
      "Traceback (most recent call last):\n",
      "  File \"C:\\Users\\Hameez\\.conda\\envs\\gpu_tf\\lib\\site-packages\\IPython\\core\\interactiveshell.py\", line 2045, in showtraceback\n",
      "    stb = value._render_traceback_()\n",
      "AttributeError: 'NameError' object has no attribute '_render_traceback_'\n",
      "\n",
      "During handling of the above exception, another exception occurred:\n",
      "\n",
      "Traceback (most recent call last):\n",
      "  File \"C:\\Users\\Hameez\\.conda\\envs\\gpu_tf\\lib\\site-packages\\IPython\\core\\interactiveshell.py\", line 3338, in run_ast_nodes\n",
      "    if (await self.run_code(code, result,  async_=asy)):\n",
      "  File \"C:\\Users\\Hameez\\.conda\\envs\\gpu_tf\\lib\\site-packages\\IPython\\core\\interactiveshell.py\", line 3435, in run_code\n",
      "    self.showtraceback(running_compiled_code=True)\n",
      "  File \"C:\\Users\\Hameez\\.conda\\envs\\gpu_tf\\lib\\site-packages\\IPython\\core\\interactiveshell.py\", line 2048, in showtraceback\n",
      "    value, tb, tb_offset=tb_offset)\n",
      "  File \"C:\\Users\\Hameez\\.conda\\envs\\gpu_tf\\lib\\site-packages\\IPython\\core\\ultratb.py\", line 1437, in structured_traceback\n",
      "    self, etype, value, tb, tb_offset, number_of_lines_of_context)\n",
      "  File \"C:\\Users\\Hameez\\.conda\\envs\\gpu_tf\\lib\\site-packages\\IPython\\core\\ultratb.py\", line 1337, in structured_traceback\n",
      "    self, etype, value, tb, tb_offset, number_of_lines_of_context\n",
      "  File \"C:\\Users\\Hameez\\.conda\\envs\\gpu_tf\\lib\\site-packages\\IPython\\core\\ultratb.py\", line 1194, in structured_traceback\n",
      "    tb_offset)\n",
      "  File \"C:\\Users\\Hameez\\.conda\\envs\\gpu_tf\\lib\\site-packages\\IPython\\core\\ultratb.py\", line 1151, in format_exception_as_a_whole\n",
      "    last_unique, recursion_repeat = find_recursion(orig_etype, evalue, records)\n",
      "  File \"C:\\Users\\Hameez\\.conda\\envs\\gpu_tf\\lib\\site-packages\\IPython\\core\\ultratb.py\", line 451, in find_recursion\n",
      "    return len(records), 0\n",
      "TypeError: object of type 'NoneType' has no len()\n",
      "\n",
      "During handling of the above exception, another exception occurred:\n",
      "\n",
      "Traceback (most recent call last):\n",
      "  File \"C:\\Users\\Hameez\\.conda\\envs\\gpu_tf\\lib\\site-packages\\IPython\\core\\interactiveshell.py\", line 2045, in showtraceback\n",
      "    stb = value._render_traceback_()\n",
      "AttributeError: 'TypeError' object has no attribute '_render_traceback_'\n",
      "\n",
      "During handling of the above exception, another exception occurred:\n",
      "\n",
      "Traceback (most recent call last):\n",
      "  File \"C:\\Users\\Hameez\\.conda\\envs\\gpu_tf\\lib\\site-packages\\IPython\\core\\ultratb.py\", line 1170, in get_records\n",
      "    return _fixed_getinnerframes(etb, number_of_lines_of_context, tb_offset)\n",
      "  File \"C:\\Users\\Hameez\\.conda\\envs\\gpu_tf\\lib\\site-packages\\IPython\\core\\ultratb.py\", line 316, in wrapped\n",
      "    return f(*args, **kwargs)\n",
      "  File \"C:\\Users\\Hameez\\.conda\\envs\\gpu_tf\\lib\\site-packages\\IPython\\core\\ultratb.py\", line 350, in _fixed_getinnerframes\n",
      "    records = fix_frame_records_filenames(inspect.getinnerframes(etb, context))\n",
      "  File \"C:\\Users\\Hameez\\.conda\\envs\\gpu_tf\\lib\\inspect.py\", line 1502, in getinnerframes\n",
      "    frameinfo = (tb.tb_frame,) + getframeinfo(tb, context)\n",
      "  File \"C:\\Users\\Hameez\\.conda\\envs\\gpu_tf\\lib\\inspect.py\", line 1460, in getframeinfo\n",
      "    filename = getsourcefile(frame) or getfile(frame)\n",
      "  File \"C:\\Users\\Hameez\\.conda\\envs\\gpu_tf\\lib\\inspect.py\", line 696, in getsourcefile\n",
      "    if getattr(getmodule(object, filename), '__loader__', None) is not None:\n",
      "  File \"C:\\Users\\Hameez\\.conda\\envs\\gpu_tf\\lib\\inspect.py\", line 733, in getmodule\n",
      "    if ismodule(module) and hasattr(module, '__file__'):\n",
      "  File \"C:\\Users\\Hameez\\.conda\\envs\\gpu_tf\\lib\\site-packages\\tensorflow\\__init__.py\", line 50, in __getattr__\n",
      "    module = self._load()\n",
      "  File \"C:\\Users\\Hameez\\.conda\\envs\\gpu_tf\\lib\\site-packages\\tensorflow\\__init__.py\", line 44, in _load\n",
      "    module = _importlib.import_module(self.__name__)\n",
      "  File \"C:\\Users\\Hameez\\.conda\\envs\\gpu_tf\\lib\\importlib\\__init__.py\", line 127, in import_module\n",
      "    return _bootstrap._gcd_import(name[level:], package, level)\n",
      "  File \"<frozen importlib._bootstrap>\", line 1006, in _gcd_import\n",
      "  File \"<frozen importlib._bootstrap>\", line 983, in _find_and_load\n",
      "  File \"<frozen importlib._bootstrap>\", line 965, in _find_and_load_unlocked\n",
      "ModuleNotFoundError: No module named 'tensorflow_core.estimator'\n",
      "Traceback (most recent call last):\n",
      "  File \"C:\\Users\\Hameez\\.conda\\envs\\gpu_tf\\lib\\site-packages\\IPython\\core\\interactiveshell.py\", line 3418, in run_code\n",
      "    exec(code_obj, self.user_global_ns, self.user_ns)\n",
      "  File \"<ipython-input-8-d737d78baf69>\", line 2, in <module>\n",
      "    plt.plot(history.history['loss'])\n",
      "NameError: name 'history' is not defined\n",
      "\n",
      "During handling of the above exception, another exception occurred:\n",
      "\n",
      "Traceback (most recent call last):\n",
      "  File \"C:\\Users\\Hameez\\.conda\\envs\\gpu_tf\\lib\\site-packages\\IPython\\core\\interactiveshell.py\", line 2045, in showtraceback\n",
      "    stb = value._render_traceback_()\n",
      "AttributeError: 'NameError' object has no attribute '_render_traceback_'\n",
      "\n",
      "During handling of the above exception, another exception occurred:\n",
      "\n",
      "Traceback (most recent call last):\n",
      "  File \"C:\\Users\\Hameez\\.conda\\envs\\gpu_tf\\lib\\site-packages\\IPython\\core\\interactiveshell.py\", line 3338, in run_ast_nodes\n",
      "    if (await self.run_code(code, result,  async_=asy)):\n",
      "  File \"C:\\Users\\Hameez\\.conda\\envs\\gpu_tf\\lib\\site-packages\\IPython\\core\\interactiveshell.py\", line 3435, in run_code\n",
      "    self.showtraceback(running_compiled_code=True)\n",
      "  File \"C:\\Users\\Hameez\\.conda\\envs\\gpu_tf\\lib\\site-packages\\IPython\\core\\interactiveshell.py\", line 2048, in showtraceback\n",
      "    value, tb, tb_offset=tb_offset)\n",
      "  File \"C:\\Users\\Hameez\\.conda\\envs\\gpu_tf\\lib\\site-packages\\IPython\\core\\ultratb.py\", line 1437, in structured_traceback\n",
      "    self, etype, value, tb, tb_offset, number_of_lines_of_context)\n",
      "  File \"C:\\Users\\Hameez\\.conda\\envs\\gpu_tf\\lib\\site-packages\\IPython\\core\\ultratb.py\", line 1337, in structured_traceback\n",
      "    self, etype, value, tb, tb_offset, number_of_lines_of_context\n",
      "  File \"C:\\Users\\Hameez\\.conda\\envs\\gpu_tf\\lib\\site-packages\\IPython\\core\\ultratb.py\", line 1194, in structured_traceback\n",
      "    tb_offset)\n",
      "  File \"C:\\Users\\Hameez\\.conda\\envs\\gpu_tf\\lib\\site-packages\\IPython\\core\\ultratb.py\", line 1151, in format_exception_as_a_whole\n",
      "    last_unique, recursion_repeat = find_recursion(orig_etype, evalue, records)\n",
      "  File \"C:\\Users\\Hameez\\.conda\\envs\\gpu_tf\\lib\\site-packages\\IPython\\core\\ultratb.py\", line 451, in find_recursion\n",
      "    return len(records), 0\n",
      "TypeError: object of type 'NoneType' has no len()\n",
      "\n",
      "During handling of the above exception, another exception occurred:\n",
      "\n",
      "Traceback (most recent call last):\n",
      "  File \"C:\\Users\\Hameez\\.conda\\envs\\gpu_tf\\lib\\site-packages\\IPython\\core\\interactiveshell.py\", line 2045, in showtraceback\n",
      "    stb = value._render_traceback_()\n",
      "AttributeError: 'TypeError' object has no attribute '_render_traceback_'\n",
      "\n",
      "During handling of the above exception, another exception occurred:\n",
      "\n",
      "Traceback (most recent call last):\n",
      "  File \"C:\\Users\\Hameez\\.conda\\envs\\gpu_tf\\lib\\site-packages\\IPython\\core\\interactiveshell.py\", line 2923, in _run_cell\n",
      "    return runner(coro)\n",
      "  File \"C:\\Users\\Hameez\\.conda\\envs\\gpu_tf\\lib\\site-packages\\IPython\\core\\async_helpers.py\", line 68, in _pseudo_sync_runner\n",
      "    coro.send(None)\n",
      "  File \"C:\\Users\\Hameez\\.conda\\envs\\gpu_tf\\lib\\site-packages\\IPython\\core\\interactiveshell.py\", line 3147, in run_cell_async\n",
      "    interactivity=interactivity, compiler=compiler, result=result)\n",
      "  File \"C:\\Users\\Hameez\\.conda\\envs\\gpu_tf\\lib\\site-packages\\IPython\\core\\interactiveshell.py\", line 3357, in run_ast_nodes\n",
      "    self.showtraceback()\n",
      "  File \"C:\\Users\\Hameez\\.conda\\envs\\gpu_tf\\lib\\site-packages\\IPython\\core\\interactiveshell.py\", line 2048, in showtraceback\n",
      "    value, tb, tb_offset=tb_offset)\n",
      "  File \"C:\\Users\\Hameez\\.conda\\envs\\gpu_tf\\lib\\site-packages\\IPython\\core\\ultratb.py\", line 1437, in structured_traceback\n",
      "    self, etype, value, tb, tb_offset, number_of_lines_of_context)\n",
      "  File \"C:\\Users\\Hameez\\.conda\\envs\\gpu_tf\\lib\\site-packages\\IPython\\core\\ultratb.py\", line 1337, in structured_traceback\n",
      "    self, etype, value, tb, tb_offset, number_of_lines_of_context\n",
      "  File \"C:\\Users\\Hameez\\.conda\\envs\\gpu_tf\\lib\\site-packages\\IPython\\core\\ultratb.py\", line 1212, in structured_traceback\n",
      "    chained_exceptions_tb_offset)\n",
      "  File \"C:\\Users\\Hameez\\.conda\\envs\\gpu_tf\\lib\\site-packages\\IPython\\core\\ultratb.py\", line 1151, in format_exception_as_a_whole\n",
      "    last_unique, recursion_repeat = find_recursion(orig_etype, evalue, records)\n",
      "  File \"C:\\Users\\Hameez\\.conda\\envs\\gpu_tf\\lib\\site-packages\\IPython\\core\\ultratb.py\", line 451, in find_recursion\n",
      "    return len(records), 0\n",
      "TypeError: object of type 'NoneType' has no len()\n",
      "\n",
      "During handling of the above exception, another exception occurred:\n",
      "\n",
      "Traceback (most recent call last):\n",
      "  File \"C:\\Users\\Hameez\\.conda\\envs\\gpu_tf\\lib\\site-packages\\IPython\\core\\interactiveshell.py\", line 2045, in showtraceback\n",
      "    stb = value._render_traceback_()\n",
      "AttributeError: 'TypeError' object has no attribute '_render_traceback_'\n",
      "\n",
      "During handling of the above exception, another exception occurred:\n",
      "\n",
      "Traceback (most recent call last):\n",
      "  File \"C:\\Users\\Hameez\\.conda\\envs\\gpu_tf\\lib\\site-packages\\IPython\\core\\ultratb.py\", line 1170, in get_records\n",
      "    return _fixed_getinnerframes(etb, number_of_lines_of_context, tb_offset)\n",
      "  File \"C:\\Users\\Hameez\\.conda\\envs\\gpu_tf\\lib\\site-packages\\IPython\\core\\ultratb.py\", line 316, in wrapped\n",
      "    return f(*args, **kwargs)\n",
      "  File \"C:\\Users\\Hameez\\.conda\\envs\\gpu_tf\\lib\\site-packages\\IPython\\core\\ultratb.py\", line 350, in _fixed_getinnerframes\n",
      "    records = fix_frame_records_filenames(inspect.getinnerframes(etb, context))\n",
      "  File \"C:\\Users\\Hameez\\.conda\\envs\\gpu_tf\\lib\\inspect.py\", line 1502, in getinnerframes\n",
      "    frameinfo = (tb.tb_frame,) + getframeinfo(tb, context)\n",
      "  File \"C:\\Users\\Hameez\\.conda\\envs\\gpu_tf\\lib\\inspect.py\", line 1460, in getframeinfo\n",
      "    filename = getsourcefile(frame) or getfile(frame)\n",
      "  File \"C:\\Users\\Hameez\\.conda\\envs\\gpu_tf\\lib\\inspect.py\", line 696, in getsourcefile\n",
      "    if getattr(getmodule(object, filename), '__loader__', None) is not None:\n",
      "  File \"C:\\Users\\Hameez\\.conda\\envs\\gpu_tf\\lib\\inspect.py\", line 733, in getmodule\n",
      "    if ismodule(module) and hasattr(module, '__file__'):\n",
      "  File \"C:\\Users\\Hameez\\.conda\\envs\\gpu_tf\\lib\\site-packages\\tensorflow\\__init__.py\", line 50, in __getattr__\n",
      "    module = self._load()\n",
      "  File \"C:\\Users\\Hameez\\.conda\\envs\\gpu_tf\\lib\\site-packages\\tensorflow\\__init__.py\", line 44, in _load\n",
      "    module = _importlib.import_module(self.__name__)\n",
      "  File \"C:\\Users\\Hameez\\.conda\\envs\\gpu_tf\\lib\\importlib\\__init__.py\", line 127, in import_module\n",
      "    return _bootstrap._gcd_import(name[level:], package, level)\n",
      "  File \"<frozen importlib._bootstrap>\", line 1006, in _gcd_import\n",
      "  File \"<frozen importlib._bootstrap>\", line 983, in _find_and_load\n",
      "  File \"<frozen importlib._bootstrap>\", line 965, in _find_and_load_unlocked\n",
      "ModuleNotFoundError: No module named 'tensorflow_core.estimator'\n"
     ]
    }
   ],
   "source": [
    "# summarize history for loss\n",
    "plt.plot(history.history['loss'])\n",
    "plt.plot(history.history['val_loss'])\n",
    "plt.title('model loss')\n",
    "plt.ylabel('loss')\n",
    "plt.xlabel('epoch')\n",
    "plt.legend(['train', 'test'], loc='upper left')\n",
    "plt.show()"
   ]
  },
  {
   "cell_type": "code",
   "execution_count": null,
   "metadata": {},
   "outputs": [],
   "source": [
    "\n",
    "model_path ='Saved Models/gs_mcl_v3.SGD_10ep.h5'\n",
    "cnn_model.save(model_path)\n",
    "\n",
    "model = tf.keras.models.load_model(model_path)"
   ]
  },
  {
   "cell_type": "code",
   "execution_count": null,
   "metadata": {},
   "outputs": [],
   "source": [
    "shape = (im_height,im_width)\n",
    "unsean_stone_path = \"C:/Users/Hameez/.conda/envs/gemstone_dataset/Data/Unseen/rutilated-quartz-zoom.jpg\"\n",
    "    \n",
    "# #img = cv2.imread(os.path.join(unsean_stones_folder)\n",
    "img = image.load_img(unsean_stone_path, target_size=shape)\n",
    "#new_img = centre_crop(img, 25)\n",
    "img_arr = image.img_to_array(img)\n",
    "print(os.path.basename(unsean_stone_path))\n",
    "img"
   ]
  },
  {
   "cell_type": "code",
   "execution_count": null,
   "metadata": {},
   "outputs": [],
   "source": [
    "img_arr = np.expand_dims(img_arr, axis=0)\n",
    "prediction = model.predict_classes(img_arr)\n",
    "classess = train_data.class_indices\n",
    "for name in classess:\n",
    "    if classess[name] == int(prediction):\n",
    "        print(\"Predicts that its a: \"+name)\n",
    "    else:\n",
    "        \"Couldn't find stone name!\"\n"
   ]
  },
  {
   "cell_type": "code",
   "execution_count": null,
   "metadata": {},
   "outputs": [],
   "source": []
  }
 ],
 "metadata": {
  "kernelspec": {
   "display_name": "gpu_tf",
   "language": "python",
   "name": "gpu_tf"
  },
  "language_info": {
   "codemirror_mode": {
    "name": "ipython",
    "version": 3
   },
   "file_extension": ".py",
   "mimetype": "text/x-python",
   "name": "python",
   "nbconvert_exporter": "python",
   "pygments_lexer": "ipython3",
   "version": "3.7.9"
  }
 },
 "nbformat": 4,
 "nbformat_minor": 4
}
