{
 "cells": [
  {
   "cell_type": "code",
   "execution_count": 1,
   "metadata": {},
   "outputs": [],
   "source": [
    "from tensorflow.keras.preprocessing.image import ImageDataGenerator, img_to_array, array_to_img\n",
    "from tensorflow.keras.preprocessing import image\n",
    "from tensorflow.keras.optimizers import RMSprop\n",
    "import tensorflow as tf\n",
    "from tensorflow import keras\n",
    "from tensorflow.keras import layers\n",
    "from tensorflow.keras.models import Sequential\n",
    "\n",
    "import matplotlib.pyplot as plt\n",
    "import numpy as np\n",
    "import pandas as pd\n",
    "import os\n",
    "from scipy import misc, ndimage\n",
    "import os\n",
    "import PIL\n",
    "\n",
    "%matplotlib inline"
   ]
  },
  {
   "cell_type": "code",
   "execution_count": 3,
   "metadata": {},
   "outputs": [
    {
     "name": "stdout",
     "output_type": "stream",
     "text": [
      "Default GPU Device:/device:GPU:0\n",
      "2.1.0\n"
     ]
    }
   ],
   "source": [
    "if tf.test.gpu_device_name(): \n",
    "    print('Default GPU Device:{}'.format(tf.test.gpu_device_name()))\n",
    "else:\n",
    "    print(\"Please install GPU version of TF\")\n",
    "print(tf.__version__)"
   ]
  },
  {
   "cell_type": "code",
   "execution_count": null,
   "metadata": {},
   "outputs": [
    {
     "name": "stderr",
     "output_type": "stream",
     "text": [
      "ERROR:root:Internal Python error in the inspect module.\n",
      "Below is the traceback from this internal error.\n",
      "\n",
      "ERROR:root:Internal Python error in the inspect module.\n",
      "Below is the traceback from this internal error.\n",
      "\n",
      "ERROR:root:Internal Python error in the inspect module.\n",
      "Below is the traceback from this internal error.\n",
      "\n"
     ]
    },
    {
     "name": "stdout",
     "output_type": "stream",
     "text": [
      "Traceback (most recent call last):\n",
      "  File \"C:\\Users\\Hameez\\.conda\\envs\\gpu_tf\\lib\\site-packages\\IPython\\core\\interactiveshell.py\", line 3418, in run_code\n",
      "    exec(code_obj, self.user_global_ns, self.user_ns)\n",
      "  File \"<ipython-input-4-28c1b5636b4a>\", line 27, in <module>\n",
      "    train_ds = tf.keras.preprocessing.image_dataset_from_directory(\n",
      "AttributeError: module 'tensorflow_core.keras.preprocessing' has no attribute 'image_dataset_from_directory'\n",
      "\n",
      "During handling of the above exception, another exception occurred:\n",
      "\n",
      "Traceback (most recent call last):\n",
      "  File \"C:\\Users\\Hameez\\.conda\\envs\\gpu_tf\\lib\\site-packages\\IPython\\core\\interactiveshell.py\", line 2045, in showtraceback\n",
      "    stb = value._render_traceback_()\n",
      "AttributeError: 'AttributeError' object has no attribute '_render_traceback_'\n",
      "\n",
      "During handling of the above exception, another exception occurred:\n",
      "\n",
      "Traceback (most recent call last):\n",
      "  File \"C:\\Users\\Hameez\\.conda\\envs\\gpu_tf\\lib\\site-packages\\IPython\\core\\ultratb.py\", line 1170, in get_records\n",
      "    return _fixed_getinnerframes(etb, number_of_lines_of_context, tb_offset)\n",
      "  File \"C:\\Users\\Hameez\\.conda\\envs\\gpu_tf\\lib\\site-packages\\IPython\\core\\ultratb.py\", line 316, in wrapped\n",
      "    return f(*args, **kwargs)\n",
      "  File \"C:\\Users\\Hameez\\.conda\\envs\\gpu_tf\\lib\\site-packages\\IPython\\core\\ultratb.py\", line 350, in _fixed_getinnerframes\n",
      "    records = fix_frame_records_filenames(inspect.getinnerframes(etb, context))\n",
      "  File \"C:\\Users\\Hameez\\.conda\\envs\\gpu_tf\\lib\\inspect.py\", line 1502, in getinnerframes\n",
      "    frameinfo = (tb.tb_frame,) + getframeinfo(tb, context)\n",
      "  File \"C:\\Users\\Hameez\\.conda\\envs\\gpu_tf\\lib\\inspect.py\", line 1460, in getframeinfo\n",
      "    filename = getsourcefile(frame) or getfile(frame)\n",
      "  File \"C:\\Users\\Hameez\\.conda\\envs\\gpu_tf\\lib\\inspect.py\", line 696, in getsourcefile\n",
      "    if getattr(getmodule(object, filename), '__loader__', None) is not None:\n",
      "  File \"C:\\Users\\Hameez\\.conda\\envs\\gpu_tf\\lib\\inspect.py\", line 733, in getmodule\n",
      "    if ismodule(module) and hasattr(module, '__file__'):\n",
      "  File \"C:\\Users\\Hameez\\.conda\\envs\\gpu_tf\\lib\\site-packages\\tensorflow\\__init__.py\", line 50, in __getattr__\n",
      "    module = self._load()\n",
      "  File \"C:\\Users\\Hameez\\.conda\\envs\\gpu_tf\\lib\\site-packages\\tensorflow\\__init__.py\", line 44, in _load\n",
      "    module = _importlib.import_module(self.__name__)\n",
      "  File \"C:\\Users\\Hameez\\.conda\\envs\\gpu_tf\\lib\\importlib\\__init__.py\", line 127, in import_module\n",
      "    return _bootstrap._gcd_import(name[level:], package, level)\n",
      "  File \"<frozen importlib._bootstrap>\", line 1006, in _gcd_import\n",
      "  File \"<frozen importlib._bootstrap>\", line 983, in _find_and_load\n",
      "  File \"<frozen importlib._bootstrap>\", line 965, in _find_and_load_unlocked\n",
      "ModuleNotFoundError: No module named 'tensorflow_core.estimator'\n",
      "Traceback (most recent call last):\n",
      "  File \"C:\\Users\\Hameez\\.conda\\envs\\gpu_tf\\lib\\site-packages\\IPython\\core\\interactiveshell.py\", line 3418, in run_code\n",
      "    exec(code_obj, self.user_global_ns, self.user_ns)\n",
      "  File \"<ipython-input-4-28c1b5636b4a>\", line 27, in <module>\n",
      "    train_ds = tf.keras.preprocessing.image_dataset_from_directory(\n",
      "AttributeError: module 'tensorflow_core.keras.preprocessing' has no attribute 'image_dataset_from_directory'\n",
      "\n",
      "During handling of the above exception, another exception occurred:\n",
      "\n",
      "Traceback (most recent call last):\n",
      "  File \"C:\\Users\\Hameez\\.conda\\envs\\gpu_tf\\lib\\site-packages\\IPython\\core\\interactiveshell.py\", line 2045, in showtraceback\n",
      "    stb = value._render_traceback_()\n",
      "AttributeError: 'AttributeError' object has no attribute '_render_traceback_'\n",
      "\n",
      "During handling of the above exception, another exception occurred:\n",
      "\n",
      "Traceback (most recent call last):\n",
      "  File \"C:\\Users\\Hameez\\.conda\\envs\\gpu_tf\\lib\\site-packages\\IPython\\core\\interactiveshell.py\", line 3338, in run_ast_nodes\n",
      "    if (await self.run_code(code, result,  async_=asy)):\n",
      "  File \"C:\\Users\\Hameez\\.conda\\envs\\gpu_tf\\lib\\site-packages\\IPython\\core\\interactiveshell.py\", line 3435, in run_code\n",
      "    self.showtraceback(running_compiled_code=True)\n",
      "  File \"C:\\Users\\Hameez\\.conda\\envs\\gpu_tf\\lib\\site-packages\\IPython\\core\\interactiveshell.py\", line 2048, in showtraceback\n",
      "    value, tb, tb_offset=tb_offset)\n",
      "  File \"C:\\Users\\Hameez\\.conda\\envs\\gpu_tf\\lib\\site-packages\\IPython\\core\\ultratb.py\", line 1437, in structured_traceback\n",
      "    self, etype, value, tb, tb_offset, number_of_lines_of_context)\n",
      "  File \"C:\\Users\\Hameez\\.conda\\envs\\gpu_tf\\lib\\site-packages\\IPython\\core\\ultratb.py\", line 1337, in structured_traceback\n",
      "    self, etype, value, tb, tb_offset, number_of_lines_of_context\n",
      "  File \"C:\\Users\\Hameez\\.conda\\envs\\gpu_tf\\lib\\site-packages\\IPython\\core\\ultratb.py\", line 1194, in structured_traceback\n",
      "    tb_offset)\n",
      "  File \"C:\\Users\\Hameez\\.conda\\envs\\gpu_tf\\lib\\site-packages\\IPython\\core\\ultratb.py\", line 1151, in format_exception_as_a_whole\n",
      "    last_unique, recursion_repeat = find_recursion(orig_etype, evalue, records)\n",
      "  File \"C:\\Users\\Hameez\\.conda\\envs\\gpu_tf\\lib\\site-packages\\IPython\\core\\ultratb.py\", line 451, in find_recursion\n",
      "    return len(records), 0\n",
      "TypeError: object of type 'NoneType' has no len()\n",
      "\n",
      "During handling of the above exception, another exception occurred:\n",
      "\n",
      "Traceback (most recent call last):\n",
      "  File \"C:\\Users\\Hameez\\.conda\\envs\\gpu_tf\\lib\\site-packages\\IPython\\core\\interactiveshell.py\", line 2045, in showtraceback\n",
      "    stb = value._render_traceback_()\n",
      "AttributeError: 'TypeError' object has no attribute '_render_traceback_'\n",
      "\n",
      "During handling of the above exception, another exception occurred:\n",
      "\n",
      "Traceback (most recent call last):\n",
      "  File \"C:\\Users\\Hameez\\.conda\\envs\\gpu_tf\\lib\\site-packages\\IPython\\core\\ultratb.py\", line 1170, in get_records\n",
      "    return _fixed_getinnerframes(etb, number_of_lines_of_context, tb_offset)\n",
      "  File \"C:\\Users\\Hameez\\.conda\\envs\\gpu_tf\\lib\\site-packages\\IPython\\core\\ultratb.py\", line 316, in wrapped\n",
      "    return f(*args, **kwargs)\n",
      "  File \"C:\\Users\\Hameez\\.conda\\envs\\gpu_tf\\lib\\site-packages\\IPython\\core\\ultratb.py\", line 350, in _fixed_getinnerframes\n",
      "    records = fix_frame_records_filenames(inspect.getinnerframes(etb, context))\n",
      "  File \"C:\\Users\\Hameez\\.conda\\envs\\gpu_tf\\lib\\inspect.py\", line 1502, in getinnerframes\n",
      "    frameinfo = (tb.tb_frame,) + getframeinfo(tb, context)\n",
      "  File \"C:\\Users\\Hameez\\.conda\\envs\\gpu_tf\\lib\\inspect.py\", line 1460, in getframeinfo\n",
      "    filename = getsourcefile(frame) or getfile(frame)\n",
      "  File \"C:\\Users\\Hameez\\.conda\\envs\\gpu_tf\\lib\\inspect.py\", line 696, in getsourcefile\n",
      "    if getattr(getmodule(object, filename), '__loader__', None) is not None:\n",
      "  File \"C:\\Users\\Hameez\\.conda\\envs\\gpu_tf\\lib\\inspect.py\", line 733, in getmodule\n",
      "    if ismodule(module) and hasattr(module, '__file__'):\n",
      "  File \"C:\\Users\\Hameez\\.conda\\envs\\gpu_tf\\lib\\site-packages\\tensorflow\\__init__.py\", line 50, in __getattr__\n",
      "    module = self._load()\n",
      "  File \"C:\\Users\\Hameez\\.conda\\envs\\gpu_tf\\lib\\site-packages\\tensorflow\\__init__.py\", line 44, in _load\n",
      "    module = _importlib.import_module(self.__name__)\n",
      "  File \"C:\\Users\\Hameez\\.conda\\envs\\gpu_tf\\lib\\importlib\\__init__.py\", line 127, in import_module\n",
      "    return _bootstrap._gcd_import(name[level:], package, level)\n",
      "  File \"<frozen importlib._bootstrap>\", line 1006, in _gcd_import\n",
      "  File \"<frozen importlib._bootstrap>\", line 983, in _find_and_load\n",
      "  File \"<frozen importlib._bootstrap>\", line 965, in _find_and_load_unlocked\n",
      "ModuleNotFoundError: No module named 'tensorflow_core.estimator'\n",
      "Traceback (most recent call last):\n",
      "  File \"C:\\Users\\Hameez\\.conda\\envs\\gpu_tf\\lib\\site-packages\\IPython\\core\\interactiveshell.py\", line 3418, in run_code\n",
      "    exec(code_obj, self.user_global_ns, self.user_ns)\n",
      "  File \"<ipython-input-4-28c1b5636b4a>\", line 27, in <module>\n",
      "    train_ds = tf.keras.preprocessing.image_dataset_from_directory(\n",
      "AttributeError: module 'tensorflow_core.keras.preprocessing' has no attribute 'image_dataset_from_directory'\n",
      "\n",
      "During handling of the above exception, another exception occurred:\n",
      "\n",
      "Traceback (most recent call last):\n",
      "  File \"C:\\Users\\Hameez\\.conda\\envs\\gpu_tf\\lib\\site-packages\\IPython\\core\\interactiveshell.py\", line 2045, in showtraceback\n",
      "    stb = value._render_traceback_()\n",
      "AttributeError: 'AttributeError' object has no attribute '_render_traceback_'\n",
      "\n",
      "During handling of the above exception, another exception occurred:\n",
      "\n",
      "Traceback (most recent call last):\n",
      "  File \"C:\\Users\\Hameez\\.conda\\envs\\gpu_tf\\lib\\site-packages\\IPython\\core\\interactiveshell.py\", line 3338, in run_ast_nodes\n",
      "    if (await self.run_code(code, result,  async_=asy)):\n",
      "  File \"C:\\Users\\Hameez\\.conda\\envs\\gpu_tf\\lib\\site-packages\\IPython\\core\\interactiveshell.py\", line 3435, in run_code\n",
      "    self.showtraceback(running_compiled_code=True)\n",
      "  File \"C:\\Users\\Hameez\\.conda\\envs\\gpu_tf\\lib\\site-packages\\IPython\\core\\interactiveshell.py\", line 2048, in showtraceback\n",
      "    value, tb, tb_offset=tb_offset)\n",
      "  File \"C:\\Users\\Hameez\\.conda\\envs\\gpu_tf\\lib\\site-packages\\IPython\\core\\ultratb.py\", line 1437, in structured_traceback\n",
      "    self, etype, value, tb, tb_offset, number_of_lines_of_context)\n",
      "  File \"C:\\Users\\Hameez\\.conda\\envs\\gpu_tf\\lib\\site-packages\\IPython\\core\\ultratb.py\", line 1337, in structured_traceback\n",
      "    self, etype, value, tb, tb_offset, number_of_lines_of_context\n",
      "  File \"C:\\Users\\Hameez\\.conda\\envs\\gpu_tf\\lib\\site-packages\\IPython\\core\\ultratb.py\", line 1194, in structured_traceback\n",
      "    tb_offset)\n",
      "  File \"C:\\Users\\Hameez\\.conda\\envs\\gpu_tf\\lib\\site-packages\\IPython\\core\\ultratb.py\", line 1151, in format_exception_as_a_whole\n",
      "    last_unique, recursion_repeat = find_recursion(orig_etype, evalue, records)\n",
      "  File \"C:\\Users\\Hameez\\.conda\\envs\\gpu_tf\\lib\\site-packages\\IPython\\core\\ultratb.py\", line 451, in find_recursion\n",
      "    return len(records), 0\n",
      "TypeError: object of type 'NoneType' has no len()\n",
      "\n",
      "During handling of the above exception, another exception occurred:\n",
      "\n",
      "Traceback (most recent call last):\n",
      "  File \"C:\\Users\\Hameez\\.conda\\envs\\gpu_tf\\lib\\site-packages\\IPython\\core\\interactiveshell.py\", line 2045, in showtraceback\n",
      "    stb = value._render_traceback_()\n",
      "AttributeError: 'TypeError' object has no attribute '_render_traceback_'\n",
      "\n",
      "During handling of the above exception, another exception occurred:\n",
      "\n",
      "Traceback (most recent call last):\n",
      "  File \"C:\\Users\\Hameez\\.conda\\envs\\gpu_tf\\lib\\site-packages\\IPython\\core\\interactiveshell.py\", line 2923, in _run_cell\n",
      "    return runner(coro)\n",
      "  File \"C:\\Users\\Hameez\\.conda\\envs\\gpu_tf\\lib\\site-packages\\IPython\\core\\async_helpers.py\", line 68, in _pseudo_sync_runner\n",
      "    coro.send(None)\n",
      "  File \"C:\\Users\\Hameez\\.conda\\envs\\gpu_tf\\lib\\site-packages\\IPython\\core\\interactiveshell.py\", line 3147, in run_cell_async\n",
      "    interactivity=interactivity, compiler=compiler, result=result)\n",
      "  File \"C:\\Users\\Hameez\\.conda\\envs\\gpu_tf\\lib\\site-packages\\IPython\\core\\interactiveshell.py\", line 3357, in run_ast_nodes\n",
      "    self.showtraceback()\n",
      "  File \"C:\\Users\\Hameez\\.conda\\envs\\gpu_tf\\lib\\site-packages\\IPython\\core\\interactiveshell.py\", line 2048, in showtraceback\n",
      "    value, tb, tb_offset=tb_offset)\n",
      "  File \"C:\\Users\\Hameez\\.conda\\envs\\gpu_tf\\lib\\site-packages\\IPython\\core\\ultratb.py\", line 1437, in structured_traceback\n",
      "    self, etype, value, tb, tb_offset, number_of_lines_of_context)\n",
      "  File \"C:\\Users\\Hameez\\.conda\\envs\\gpu_tf\\lib\\site-packages\\IPython\\core\\ultratb.py\", line 1337, in structured_traceback\n",
      "    self, etype, value, tb, tb_offset, number_of_lines_of_context\n",
      "  File \"C:\\Users\\Hameez\\.conda\\envs\\gpu_tf\\lib\\site-packages\\IPython\\core\\ultratb.py\", line 1212, in structured_traceback\n",
      "    chained_exceptions_tb_offset)\n",
      "  File \"C:\\Users\\Hameez\\.conda\\envs\\gpu_tf\\lib\\site-packages\\IPython\\core\\ultratb.py\", line 1151, in format_exception_as_a_whole\n",
      "    last_unique, recursion_repeat = find_recursion(orig_etype, evalue, records)\n",
      "  File \"C:\\Users\\Hameez\\.conda\\envs\\gpu_tf\\lib\\site-packages\\IPython\\core\\ultratb.py\", line 451, in find_recursion\n",
      "    return len(records), 0\n",
      "TypeError: object of type 'NoneType' has no len()\n",
      "\n",
      "During handling of the above exception, another exception occurred:\n",
      "\n",
      "Traceback (most recent call last):\n",
      "  File \"C:\\Users\\Hameez\\.conda\\envs\\gpu_tf\\lib\\site-packages\\IPython\\core\\interactiveshell.py\", line 2045, in showtraceback\n",
      "    stb = value._render_traceback_()\n",
      "AttributeError: 'TypeError' object has no attribute '_render_traceback_'\n",
      "\n",
      "During handling of the above exception, another exception occurred:\n",
      "\n",
      "Traceback (most recent call last):\n",
      "  File \"C:\\Users\\Hameez\\.conda\\envs\\gpu_tf\\lib\\site-packages\\IPython\\core\\ultratb.py\", line 1170, in get_records\n",
      "    return _fixed_getinnerframes(etb, number_of_lines_of_context, tb_offset)\n",
      "  File \"C:\\Users\\Hameez\\.conda\\envs\\gpu_tf\\lib\\site-packages\\IPython\\core\\ultratb.py\", line 316, in wrapped\n",
      "    return f(*args, **kwargs)\n",
      "  File \"C:\\Users\\Hameez\\.conda\\envs\\gpu_tf\\lib\\site-packages\\IPython\\core\\ultratb.py\", line 350, in _fixed_getinnerframes\n",
      "    records = fix_frame_records_filenames(inspect.getinnerframes(etb, context))\n",
      "  File \"C:\\Users\\Hameez\\.conda\\envs\\gpu_tf\\lib\\inspect.py\", line 1502, in getinnerframes\n",
      "    frameinfo = (tb.tb_frame,) + getframeinfo(tb, context)\n",
      "  File \"C:\\Users\\Hameez\\.conda\\envs\\gpu_tf\\lib\\inspect.py\", line 1460, in getframeinfo\n",
      "    filename = getsourcefile(frame) or getfile(frame)\n",
      "  File \"C:\\Users\\Hameez\\.conda\\envs\\gpu_tf\\lib\\inspect.py\", line 696, in getsourcefile\n",
      "    if getattr(getmodule(object, filename), '__loader__', None) is not None:\n",
      "  File \"C:\\Users\\Hameez\\.conda\\envs\\gpu_tf\\lib\\inspect.py\", line 733, in getmodule\n",
      "    if ismodule(module) and hasattr(module, '__file__'):\n",
      "  File \"C:\\Users\\Hameez\\.conda\\envs\\gpu_tf\\lib\\site-packages\\tensorflow\\__init__.py\", line 50, in __getattr__\n",
      "    module = self._load()\n",
      "  File \"C:\\Users\\Hameez\\.conda\\envs\\gpu_tf\\lib\\site-packages\\tensorflow\\__init__.py\", line 44, in _load\n",
      "    module = _importlib.import_module(self.__name__)\n",
      "  File \"C:\\Users\\Hameez\\.conda\\envs\\gpu_tf\\lib\\importlib\\__init__.py\", line 127, in import_module\n",
      "    return _bootstrap._gcd_import(name[level:], package, level)\n",
      "  File \"<frozen importlib._bootstrap>\", line 1006, in _gcd_import\n",
      "  File \"<frozen importlib._bootstrap>\", line 983, in _find_and_load\n",
      "  File \"<frozen importlib._bootstrap>\", line 965, in _find_and_load_unlocked\n",
      "ModuleNotFoundError: No module named 'tensorflow_core.estimator'\n"
     ]
    }
   ],
   "source": [
    "#import Data\n",
    "\n",
    "train_folder = \"Data/Train/\"\n",
    "test_folder = \"Data/Test/\"\n",
    "\n",
    "\n",
    "# img = image.load_img(train_folder+\"/Alexandrite/alexandrite_2.jpg\")\n",
    "# # plt.imshow(img)\n",
    "# # plt.show()\n",
    "# print(cv2.imread(\"Data/Train/Alexandrite/alexandrite_24.jpg\").shape)\n",
    "\n",
    "#------------augmentation for train images----------------------------------#\n",
    "train = ImageDataGenerator(rescale=1/255)\n",
    "#---------------------------------------------------------------------------#\n",
    "\n",
    "test = ImageDataGenerator(rescale=1/255)\n",
    "\n",
    "\n",
    "# train_data = train.flow_from_directory(train_folder,\n",
    "#                                        target_size=(256,256),\n",
    "#                                        class_mode='categorical')\n",
    "# test_data = test.flow_from_directory(test_folder,\n",
    "#                                        target_size=(256,256),\n",
    "#                                        class_mode='categorical')\n",
    "\n",
    "\n",
    "train_ds = tf.keras.preprocessing.image_dataset_from_directory(\n",
    "    train_folder,\n",
    "    image_size=(200, 200),\n",
    "    batch_size=32)\n",
    "\n",
    "val_ds = tf.keras.preprocessing.image_dataset_from_directory(\n",
    "    test_folder,\n",
    "    image_size=(200, 200),\n",
    "    batch_size=32)"
   ]
  },
  {
   "cell_type": "code",
   "execution_count": null,
   "metadata": {},
   "outputs": [],
   "source": [
    "class_names = train_ds.class_names\n",
    "plt.figure(figsize=(10, 10))\n",
    "for images, labels in train_ds.take(1):\n",
    "    for i in range(9):\n",
    "        ax = plt.subplot(3, 3, i + 1)\n",
    "        plt.imshow(images[i].numpy().astype(\"uint8\"))\n",
    "        plt.title(class_names[labels[i]])\n",
    "        plt.axis(\"off\")\n"
   ]
  },
  {
   "cell_type": "code",
   "execution_count": null,
   "metadata": {},
   "outputs": [],
   "source": [
    "for image_batch, labels_batch in train_ds:\n",
    "    print(image_batch.shape)\n",
    "    print(labels_batch.shape)\n",
    "    break"
   ]
  },
  {
   "cell_type": "code",
   "execution_count": null,
   "metadata": {},
   "outputs": [],
   "source": [
    "AUTOTUNE = tf.data.experimental.AUTOTUNE\n",
    "\n",
    "train_ds = train_ds.cache().shuffle(1000).prefetch(buffer_size=AUTOTUNE)\n",
    "val_ds = val_ds.cache().prefetch(buffer_size=AUTOTUNE)"
   ]
  },
  {
   "cell_type": "code",
   "execution_count": null,
   "metadata": {},
   "outputs": [],
   "source": [
    "normalization_layer = layers.experimental.preprocessing.Rescaling(1./255)"
   ]
  },
  {
   "cell_type": "code",
   "execution_count": null,
   "metadata": {},
   "outputs": [],
   "source": [
    "normalized_ds = train_ds.map(lambda x, y: (normalization_layer(x), y))\n",
    "image_batch, labels_batch = next(iter(normalized_ds))\n",
    "first_image = image_batch[0]\n",
    "# Notice the pixels values are now in `[0,1]`.\n",
    "print(np.min(first_image), np.max(first_image)) "
   ]
  },
  {
   "cell_type": "code",
   "execution_count": null,
   "metadata": {},
   "outputs": [],
   "source": [
    "num_classes = 87\n",
    "\n",
    "model = Sequential([\n",
    "  layers.experimental.preprocessing.Rescaling(1./255, input_shape=(200, 200, 3)),\n",
    "  layers.Conv2D(16, 3, padding='same', activation='relu'),\n",
    "  layers.MaxPooling2D(),\n",
    "  layers.Conv2D(32, 3, padding='same', activation='relu'),\n",
    "  layers.MaxPooling2D(),\n",
    "  layers.Conv2D(64, 3, padding='same', activation='relu'),\n",
    "  layers.MaxPooling2D(),\n",
    "  layers.Flatten(),\n",
    "  layers.Dense(128, activation='relu'),\n",
    "  layers.Dense(num_classes)\n",
    "])"
   ]
  },
  {
   "cell_type": "code",
   "execution_count": null,
   "metadata": {},
   "outputs": [],
   "source": [
    "model.compile(optimizer='adam',\n",
    "              loss=tf.keras.losses.SparseCategoricalCrossentropy(from_logits=True),\n",
    "              metrics=['accuracy'])"
   ]
  },
  {
   "cell_type": "code",
   "execution_count": null,
   "metadata": {},
   "outputs": [],
   "source": [
    "model.summary()"
   ]
  },
  {
   "cell_type": "code",
   "execution_count": null,
   "metadata": {},
   "outputs": [],
   "source": [
    "epochs=10\n",
    "history = model.fit(\n",
    "  train_ds,\n",
    "  validation_data=val_ds,\n",
    "  epochs=epochs\n",
    ")"
   ]
  },
  {
   "cell_type": "code",
   "execution_count": null,
   "metadata": {},
   "outputs": [],
   "source": [
    "acc = history.history['accuracy']\n",
    "val_acc = history.history['val_accuracy']\n",
    "\n",
    "loss = history.history['loss']\n",
    "val_loss = history.history['val_loss']\n",
    "\n",
    "epochs_range = range(epochs)\n",
    "\n",
    "plt.figure(figsize=(8, 8))\n",
    "plt.subplot(1, 2, 1)\n",
    "plt.plot(epochs_range, acc, label='Training Accuracy')\n",
    "plt.plot(epochs_range, val_acc, label='Validation Accuracy')\n",
    "plt.legend(loc='lower right')\n",
    "plt.title('Training and Validation Accuracy')\n",
    "\n",
    "plt.subplot(1, 2, 2)\n",
    "plt.plot(epochs_range, loss, label='Training Loss')\n",
    "plt.plot(epochs_range, val_loss, label='Validation Loss')\n",
    "plt.legend(loc='upper right')\n",
    "plt.title('Training and Validation Loss')\n",
    "plt.show()"
   ]
  },
  {
   "cell_type": "code",
   "execution_count": null,
   "metadata": {},
   "outputs": [],
   "source": [
    "# test_augment = ImageDataGenerator(rescale=1/255, rotation_range=90,\n",
    "#                           width_shift_range=0.2, height_shift_range=0.1,\n",
    "#                           shear_range=0.25, channel_shift_range=10.,horizontal_flip=True, vertical_flip=True)\n",
    "# img = image.load_img(train_folder+\"/Alexandrite/alexandrite_5.jpg\")\n",
    "# plt.imshow(img)\n",
    "\n"
   ]
  },
  {
   "cell_type": "code",
   "execution_count": null,
   "metadata": {},
   "outputs": [],
   "source": [
    "# x = img_to_array(img)\n",
    "# x = x.reshape((1,) + x.shape)\n",
    "\n",
    "# i = 0\n",
    "# for batch in test_augment.flow(x, batch_size=1,\n",
    "#                               save_to_dir='Augmented', save_prefix='alexandrite',\n",
    "#                                save_format='jpeg',):\n",
    "#     i += 1\n",
    "#     if i > 20:\n",
    "#         break"
   ]
  },
  {
   "cell_type": "code",
   "execution_count": null,
   "metadata": {},
   "outputs": [],
   "source": [
    "\n",
    "cnn_model = tf.keras.models.Sequential([tf.keras.layers.Conv2D(16,(3,3),activation='relu',input_shape=(256,256,3)),\n",
    "                                        tf.keras.layers.MaxPool2D(2,2),\n",
    "                                        #\n",
    "                                        tf.keras.layers.Conv2D(32,(3,3),activation='relu'),\n",
    "                                        tf.keras.layers.MaxPool2D(2,2),\n",
    "                                        #\n",
    "                                        tf.keras.layers.Conv2D(64,(3,3),activation='relu'),\n",
    "                                        tf.keras.layers.MaxPool2D(2,2),\n",
    "                                        #\n",
    "                                        tf.keras.layers.Conv2D(128,(3,3),activation='relu'),\n",
    "                                        tf.keras.layers.MaxPool2D(2,2),\n",
    "                                        #\n",
    "                                        tf.keras.layers.Conv2D(256,(3,3),activation='relu'),\n",
    "                                        tf.keras.layers.MaxPool2D(2,2),\n",
    "                                        #\n",
    "                                        tf.keras.layers.Flatten(),\n",
    "                                        ##\n",
    "                                        tf.keras.layers.Dense(128, activation='relu'),\n",
    "                                        ##\n",
    "                                        tf.keras.layers.Dense(256, activation='relu'),\n",
    "                                        ##\n",
    "                                        tf.keras.layers.Dense(512, activation='relu'),\n",
    "                                        ##\n",
    "                                        tf.keras.layers.Dense(87, activation='softmax')\n",
    "                                        ])\n",
    "cnn_model.summary()\n"
   ]
  },
  {
   "cell_type": "code",
   "execution_count": null,
   "metadata": {},
   "outputs": [],
   "source": [
    "cnn_model.compile(loss='categorical_crossentropy',\n",
    "                  optimizer='Adam',\n",
    "                  metrics=['accuracy'])\n",
    "\n",
    "history = cnn_model.fit_generator(train_data, epochs=50, validation_data=test_data, verbose=1)"
   ]
  },
  {
   "cell_type": "code",
   "execution_count": null,
   "metadata": {},
   "outputs": [],
   "source": []
  },
  {
   "cell_type": "code",
   "execution_count": null,
   "metadata": {},
   "outputs": [],
   "source": [
    "# summarize history for accuracy\n",
    "plt.plot(history.history['accuracy'])\n",
    "plt.plot(history.history['val_accuracy'])\n",
    "plt.title('model accuracy')\n",
    "plt.ylabel('accuracy')\n",
    "plt.xlabel('epoch')\n",
    "plt.legend(['train', 'test'], loc='upper left')\n",
    "plt.show()"
   ]
  },
  {
   "cell_type": "code",
   "execution_count": null,
   "metadata": {},
   "outputs": [],
   "source": [
    "# summarize history for loss\n",
    "plt.plot(history.history['loss'])\n",
    "plt.plot(history.history['val_loss'])\n",
    "plt.title('model loss')\n",
    "plt.ylabel('loss')\n",
    "plt.xlabel('epoch')\n",
    "plt.legend(['train', 'test'], loc='upper left')\n",
    "plt.show()"
   ]
  },
  {
   "cell_type": "code",
   "execution_count": null,
   "metadata": {},
   "outputs": [],
   "source": [
    "\n",
    "model_path ='Saved Models/gs_mcl_v1.5.h5'\n",
    "cnn_model.save(model_path)\n",
    "\n",
    "model = tf.keras.models.load_model(model_path)"
   ]
  },
  {
   "cell_type": "code",
   "execution_count": null,
   "metadata": {},
   "outputs": [],
   "source": [
    "shape = (256, 256)\n",
    "unsean_stone_path = \"Data/Unseen/emerald_2.jpg\"\n",
    "\n",
    "# #img = cv2.imread(os.path.join(unsean_stones_folder)\n",
    "img = image.load_img(unsean_stone_path, target_size=shape)\n",
    "img_arr = image.img_to_array(img)\n",
    "print(os.path.basename(unsean_stone_path))\n",
    "img"
   ]
  },
  {
   "cell_type": "code",
   "execution_count": null,
   "metadata": {},
   "outputs": [],
   "source": [
    "img_arr = np.expand_dims(img_arr, axis=0)\n",
    "prediction = model.predict_classes(img_arr)\n",
    "classess = train_data.class_indices\n",
    "for name in classess:\n",
    "    if classess[name] == int(prediction):\n",
    "        print(\"Predicts that its a: \"+name)\n",
    "    else:\n",
    "        \"Couldn't find stone name!\"\n"
   ]
  },
  {
   "cell_type": "code",
   "execution_count": null,
   "metadata": {},
   "outputs": [],
   "source": []
  }
 ],
 "metadata": {
  "kernelspec": {
   "display_name": "gpu_tf",
   "language": "python",
   "name": "gpu_tf"
  },
  "language_info": {
   "codemirror_mode": {
    "name": "ipython",
    "version": 3
   },
   "file_extension": ".py",
   "mimetype": "text/x-python",
   "name": "python",
   "nbconvert_exporter": "python",
   "pygments_lexer": "ipython3",
   "version": "3.7.9"
  }
 },
 "nbformat": 4,
 "nbformat_minor": 4
}
